2016-08-03 01:46:43,453 [Thread-15:140249453057792] [django.request:170] [base:get_response] [WARNING]- Not Found: /favicon.ico
2016-08-03 03:46:20,943 [Thread-22:140249453057792] [django.request:170] [base:get_response] [WARNING]- Not Found: /
2016-08-03 03:46:46,911 [Thread-36:140249421588224] [django.request:170] [base:get_response] [WARNING]- Not Found: /favicon.ico
2016-08-03 05:06:45,196 [Thread-126:140249453057792] [django.request:170] [base:get_response] [WARNING]- Not Found: /
2016-08-03 06:23:50,989 [Thread-129:140249453057792] [django.request:170] [base:get_response] [WARNING]- Not Found: /
2016-08-03 06:36:41,819 [Thread-2:140034992764672] [django.request:256] [base:handle_uncaught_exception] [ERROR]- Internal Server Error: /api/v1/snippets/
Traceback (most recent call last):
  File "/server/software/pyenv/versions/2.7.5/lib/python2.7/site-packages/django/core/handlers/base.py", line 119, in get_response
    resolver_match = resolver.resolve(request.path_info)
  File "/server/software/pyenv/versions/2.7.5/lib/python2.7/site-packages/django/core/urlresolvers.py", line 366, in resolve
    for pattern in self.url_patterns:
  File "/server/software/pyenv/versions/2.7.5/lib/python2.7/site-packages/django/core/urlresolvers.py", line 402, in url_patterns
    patterns = getattr(self.urlconf_module, "urlpatterns", self.urlconf_module)
  File "/server/software/pyenv/versions/2.7.5/lib/python2.7/site-packages/django/core/urlresolvers.py", line 396, in urlconf_module
    self._urlconf_module = import_module(self.urlconf_name)
  File "/server/software/pyenv/versions/2.7.5/lib/python2.7/importlib/__init__.py", line 37, in import_module
    __import__(name)
  File "/server/software/OpManage/OpManage/urls.py", line 20, in <module>
    url(r'^api/v1/',include('Api.urls')),
  File "/server/software/pyenv/versions/2.7.5/lib/python2.7/site-packages/django/conf/urls/__init__.py", line 33, in include
    urlconf_module = import_module(urlconf_module)
  File "/server/software/pyenv/versions/2.7.5/lib/python2.7/importlib/__init__.py", line 37, in import_module
    __import__(name)
  File "/server/software/OpManage/Api/urls.py", line 15, in <module>
    router.register('users','Api.views.UserViewSet')
  File "/server/software/pyenv/versions/2.7.5/lib/python2.7/site-packages/rest_framework/routers.py", line 62, in register
    base_name = self.get_default_base_name(viewset)
  File "/server/software/pyenv/versions/2.7.5/lib/python2.7/site-packages/rest_framework/routers.py", line 137, in get_default_base_name
    assert queryset is not None, '`base_name` argument not specified, and could ' \
AssertionError: `base_name` argument not specified, and could not automatically determine the name from the viewset, as it does not have a `.queryset` attribute.
2016-08-03 06:37:49,597 [Thread-3:140034992764672] [django.request:256] [base:handle_uncaught_exception] [ERROR]- Internal Server Error: /api/v1/snippets/
Traceback (most recent call last):
  File "/server/software/pyenv/versions/2.7.5/lib/python2.7/site-packages/django/core/handlers/base.py", line 119, in get_response
    resolver_match = resolver.resolve(request.path_info)
  File "/server/software/pyenv/versions/2.7.5/lib/python2.7/site-packages/django/core/urlresolvers.py", line 366, in resolve
    for pattern in self.url_patterns:
  File "/server/software/pyenv/versions/2.7.5/lib/python2.7/site-packages/django/core/urlresolvers.py", line 402, in url_patterns
    patterns = getattr(self.urlconf_module, "urlpatterns", self.urlconf_module)
  File "/server/software/pyenv/versions/2.7.5/lib/python2.7/site-packages/django/core/urlresolvers.py", line 396, in urlconf_module
    self._urlconf_module = import_module(self.urlconf_name)
  File "/server/software/pyenv/versions/2.7.5/lib/python2.7/importlib/__init__.py", line 37, in import_module
    __import__(name)
  File "/server/software/OpManage/OpManage/urls.py", line 20, in <module>
    url(r'^api/v1/',include('Api.urls')),
  File "/server/software/pyenv/versions/2.7.5/lib/python2.7/site-packages/django/conf/urls/__init__.py", line 33, in include
    urlconf_module = import_module(urlconf_module)
  File "/server/software/pyenv/versions/2.7.5/lib/python2.7/importlib/__init__.py", line 37, in import_module
    __import__(name)
  File "/server/software/OpManage/Api/urls.py", line 15, in <module>
    router.register('users','Api.views.UserViewSet')
  File "/server/software/pyenv/versions/2.7.5/lib/python2.7/site-packages/rest_framework/routers.py", line 62, in register
    base_name = self.get_default_base_name(viewset)
  File "/server/software/pyenv/versions/2.7.5/lib/python2.7/site-packages/rest_framework/routers.py", line 137, in get_default_base_name
    assert queryset is not None, '`base_name` argument not specified, and could ' \
AssertionError: `base_name` argument not specified, and could not automatically determine the name from the viewset, as it does not have a `.queryset` attribute.
2016-08-03 06:37:50,927 [Thread-4:140034992764672] [django.request:256] [base:handle_uncaught_exception] [ERROR]- Internal Server Error: /api/v1/snippets/
Traceback (most recent call last):
  File "/server/software/pyenv/versions/2.7.5/lib/python2.7/site-packages/django/core/handlers/base.py", line 119, in get_response
    resolver_match = resolver.resolve(request.path_info)
  File "/server/software/pyenv/versions/2.7.5/lib/python2.7/site-packages/django/core/urlresolvers.py", line 366, in resolve
    for pattern in self.url_patterns:
  File "/server/software/pyenv/versions/2.7.5/lib/python2.7/site-packages/django/core/urlresolvers.py", line 402, in url_patterns
    patterns = getattr(self.urlconf_module, "urlpatterns", self.urlconf_module)
  File "/server/software/pyenv/versions/2.7.5/lib/python2.7/site-packages/django/core/urlresolvers.py", line 396, in urlconf_module
    self._urlconf_module = import_module(self.urlconf_name)
  File "/server/software/pyenv/versions/2.7.5/lib/python2.7/importlib/__init__.py", line 37, in import_module
    __import__(name)
  File "/server/software/OpManage/OpManage/urls.py", line 20, in <module>
    url(r'^api/v1/',include('Api.urls')),
  File "/server/software/pyenv/versions/2.7.5/lib/python2.7/site-packages/django/conf/urls/__init__.py", line 33, in include
    urlconf_module = import_module(urlconf_module)
  File "/server/software/pyenv/versions/2.7.5/lib/python2.7/importlib/__init__.py", line 37, in import_module
    __import__(name)
  File "/server/software/OpManage/Api/urls.py", line 15, in <module>
    router.register('users','Api.views.UserViewSet')
  File "/server/software/pyenv/versions/2.7.5/lib/python2.7/site-packages/rest_framework/routers.py", line 62, in register
    base_name = self.get_default_base_name(viewset)
  File "/server/software/pyenv/versions/2.7.5/lib/python2.7/site-packages/rest_framework/routers.py", line 137, in get_default_base_name
    assert queryset is not None, '`base_name` argument not specified, and could ' \
AssertionError: `base_name` argument not specified, and could not automatically determine the name from the viewset, as it does not have a `.queryset` attribute.
2016-08-03 06:38:00,351 [Thread-5:140034992764672] [django.request:256] [base:handle_uncaught_exception] [ERROR]- Internal Server Error: /api/v1/snippets/
Traceback (most recent call last):
  File "/server/software/pyenv/versions/2.7.5/lib/python2.7/site-packages/django/core/handlers/base.py", line 119, in get_response
    resolver_match = resolver.resolve(request.path_info)
  File "/server/software/pyenv/versions/2.7.5/lib/python2.7/site-packages/django/core/urlresolvers.py", line 366, in resolve
    for pattern in self.url_patterns:
  File "/server/software/pyenv/versions/2.7.5/lib/python2.7/site-packages/django/core/urlresolvers.py", line 402, in url_patterns
    patterns = getattr(self.urlconf_module, "urlpatterns", self.urlconf_module)
  File "/server/software/pyenv/versions/2.7.5/lib/python2.7/site-packages/django/core/urlresolvers.py", line 396, in urlconf_module
    self._urlconf_module = import_module(self.urlconf_name)
  File "/server/software/pyenv/versions/2.7.5/lib/python2.7/importlib/__init__.py", line 37, in import_module
    __import__(name)
  File "/server/software/OpManage/OpManage/urls.py", line 20, in <module>
    url(r'^api/v1/',include('Api.urls')),
  File "/server/software/pyenv/versions/2.7.5/lib/python2.7/site-packages/django/conf/urls/__init__.py", line 33, in include
    urlconf_module = import_module(urlconf_module)
  File "/server/software/pyenv/versions/2.7.5/lib/python2.7/importlib/__init__.py", line 37, in import_module
    __import__(name)
  File "/server/software/OpManage/Api/urls.py", line 15, in <module>
    router.register('users','Api.views.UserViewSet')
  File "/server/software/pyenv/versions/2.7.5/lib/python2.7/site-packages/rest_framework/routers.py", line 62, in register
    base_name = self.get_default_base_name(viewset)
  File "/server/software/pyenv/versions/2.7.5/lib/python2.7/site-packages/rest_framework/routers.py", line 137, in get_default_base_name
    assert queryset is not None, '`base_name` argument not specified, and could ' \
AssertionError: `base_name` argument not specified, and could not automatically determine the name from the viewset, as it does not have a `.queryset` attribute.
2016-08-03 06:38:41,665 [Thread-6:140034992764672] [django.request:256] [base:handle_uncaught_exception] [ERROR]- Internal Server Error: /api/v1/snippets/
Traceback (most recent call last):
  File "/server/software/pyenv/versions/2.7.5/lib/python2.7/site-packages/django/core/handlers/base.py", line 119, in get_response
    resolver_match = resolver.resolve(request.path_info)
  File "/server/software/pyenv/versions/2.7.5/lib/python2.7/site-packages/django/core/urlresolvers.py", line 366, in resolve
    for pattern in self.url_patterns:
  File "/server/software/pyenv/versions/2.7.5/lib/python2.7/site-packages/django/core/urlresolvers.py", line 402, in url_patterns
    patterns = getattr(self.urlconf_module, "urlpatterns", self.urlconf_module)
  File "/server/software/pyenv/versions/2.7.5/lib/python2.7/site-packages/django/core/urlresolvers.py", line 396, in urlconf_module
    self._urlconf_module = import_module(self.urlconf_name)
  File "/server/software/pyenv/versions/2.7.5/lib/python2.7/importlib/__init__.py", line 37, in import_module
    __import__(name)
  File "/server/software/OpManage/OpManage/urls.py", line 20, in <module>
    url(r'^api/v1/',include('Api.urls')),
  File "/server/software/pyenv/versions/2.7.5/lib/python2.7/site-packages/django/conf/urls/__init__.py", line 33, in include
    urlconf_module = import_module(urlconf_module)
  File "/server/software/pyenv/versions/2.7.5/lib/python2.7/importlib/__init__.py", line 37, in import_module
    __import__(name)
  File "/server/software/OpManage/Api/urls.py", line 15, in <module>
    router.register('users','Api.views.UserViewSet')
  File "/server/software/pyenv/versions/2.7.5/lib/python2.7/site-packages/rest_framework/routers.py", line 62, in register
    base_name = self.get_default_base_name(viewset)
  File "/server/software/pyenv/versions/2.7.5/lib/python2.7/site-packages/rest_framework/routers.py", line 137, in get_default_base_name
    assert queryset is not None, '`base_name` argument not specified, and could ' \
AssertionError: `base_name` argument not specified, and could not automatically determine the name from the viewset, as it does not have a `.queryset` attribute.
2016-08-03 06:38:42,973 [Thread-7:140034992764672] [django.request:256] [base:handle_uncaught_exception] [ERROR]- Internal Server Error: /api/v1/snippets/
Traceback (most recent call last):
  File "/server/software/pyenv/versions/2.7.5/lib/python2.7/site-packages/django/core/handlers/base.py", line 119, in get_response
    resolver_match = resolver.resolve(request.path_info)
  File "/server/software/pyenv/versions/2.7.5/lib/python2.7/site-packages/django/core/urlresolvers.py", line 366, in resolve
    for pattern in self.url_patterns:
  File "/server/software/pyenv/versions/2.7.5/lib/python2.7/site-packages/django/core/urlresolvers.py", line 402, in url_patterns
    patterns = getattr(self.urlconf_module, "urlpatterns", self.urlconf_module)
  File "/server/software/pyenv/versions/2.7.5/lib/python2.7/site-packages/django/core/urlresolvers.py", line 396, in urlconf_module
    self._urlconf_module = import_module(self.urlconf_name)
  File "/server/software/pyenv/versions/2.7.5/lib/python2.7/importlib/__init__.py", line 37, in import_module
    __import__(name)
  File "/server/software/OpManage/OpManage/urls.py", line 20, in <module>
    url(r'^api/v1/',include('Api.urls')),
  File "/server/software/pyenv/versions/2.7.5/lib/python2.7/site-packages/django/conf/urls/__init__.py", line 33, in include
    urlconf_module = import_module(urlconf_module)
  File "/server/software/pyenv/versions/2.7.5/lib/python2.7/importlib/__init__.py", line 37, in import_module
    __import__(name)
  File "/server/software/OpManage/Api/urls.py", line 15, in <module>
    router.register('users','Api.views.UserViewSet')
  File "/server/software/pyenv/versions/2.7.5/lib/python2.7/site-packages/rest_framework/routers.py", line 62, in register
    base_name = self.get_default_base_name(viewset)
  File "/server/software/pyenv/versions/2.7.5/lib/python2.7/site-packages/rest_framework/routers.py", line 137, in get_default_base_name
    assert queryset is not None, '`base_name` argument not specified, and could ' \
AssertionError: `base_name` argument not specified, and could not automatically determine the name from the viewset, as it does not have a `.queryset` attribute.
2016-08-03 06:40:10,722 [Thread-2:140680577693440] [django.request:256] [base:handle_uncaught_exception] [ERROR]- Internal Server Error: /api/v1/
Traceback (most recent call last):
  File "/server/software/pyenv/versions/2.7.5/lib/python2.7/site-packages/django/core/handlers/base.py", line 119, in get_response
    resolver_match = resolver.resolve(request.path_info)
  File "/server/software/pyenv/versions/2.7.5/lib/python2.7/site-packages/django/core/urlresolvers.py", line 366, in resolve
    for pattern in self.url_patterns:
  File "/server/software/pyenv/versions/2.7.5/lib/python2.7/site-packages/django/core/urlresolvers.py", line 402, in url_patterns
    patterns = getattr(self.urlconf_module, "urlpatterns", self.urlconf_module)
  File "/server/software/pyenv/versions/2.7.5/lib/python2.7/site-packages/django/core/urlresolvers.py", line 396, in urlconf_module
    self._urlconf_module = import_module(self.urlconf_name)
  File "/server/software/pyenv/versions/2.7.5/lib/python2.7/importlib/__init__.py", line 37, in import_module
    __import__(name)
  File "/server/software/OpManage/OpManage/urls.py", line 9, in <module>
    admin.autodiscover()
NameError: name 'admin' is not defined
2016-08-03 06:40:24,132 [Thread-3:140680577693440] [django.request:256] [base:handle_uncaught_exception] [ERROR]- Internal Server Error: /api/v1/
Traceback (most recent call last):
  File "/server/software/pyenv/versions/2.7.5/lib/python2.7/site-packages/django/core/handlers/base.py", line 119, in get_response
    resolver_match = resolver.resolve(request.path_info)
  File "/server/software/pyenv/versions/2.7.5/lib/python2.7/site-packages/django/core/urlresolvers.py", line 366, in resolve
    for pattern in self.url_patterns:
  File "/server/software/pyenv/versions/2.7.5/lib/python2.7/site-packages/django/core/urlresolvers.py", line 402, in url_patterns
    patterns = getattr(self.urlconf_module, "urlpatterns", self.urlconf_module)
  File "/server/software/pyenv/versions/2.7.5/lib/python2.7/site-packages/django/core/urlresolvers.py", line 396, in urlconf_module
    self._urlconf_module = import_module(self.urlconf_name)
  File "/server/software/pyenv/versions/2.7.5/lib/python2.7/importlib/__init__.py", line 37, in import_module
    __import__(name)
  File "/server/software/OpManage/OpManage/urls.py", line 9, in <module>
    admin.autodiscover()
NameError: name 'admin' is not defined
2016-08-03 06:40:25,398 [Thread-4:140680577693440] [django.request:256] [base:handle_uncaught_exception] [ERROR]- Internal Server Error: /api/v1/
Traceback (most recent call last):
  File "/server/software/pyenv/versions/2.7.5/lib/python2.7/site-packages/django/core/handlers/base.py", line 119, in get_response
    resolver_match = resolver.resolve(request.path_info)
  File "/server/software/pyenv/versions/2.7.5/lib/python2.7/site-packages/django/core/urlresolvers.py", line 366, in resolve
    for pattern in self.url_patterns:
  File "/server/software/pyenv/versions/2.7.5/lib/python2.7/site-packages/django/core/urlresolvers.py", line 402, in url_patterns
    patterns = getattr(self.urlconf_module, "urlpatterns", self.urlconf_module)
  File "/server/software/pyenv/versions/2.7.5/lib/python2.7/site-packages/django/core/urlresolvers.py", line 396, in urlconf_module
    self._urlconf_module = import_module(self.urlconf_name)
  File "/server/software/pyenv/versions/2.7.5/lib/python2.7/importlib/__init__.py", line 37, in import_module
    __import__(name)
  File "/server/software/OpManage/OpManage/urls.py", line 9, in <module>
    admin.autodiscover()
NameError: name 'admin' is not defined
2016-08-03 06:40:26,373 [Thread-5:140680577693440] [django.request:256] [base:handle_uncaught_exception] [ERROR]- Internal Server Error: /api/v1/
Traceback (most recent call last):
  File "/server/software/pyenv/versions/2.7.5/lib/python2.7/site-packages/django/core/handlers/base.py", line 119, in get_response
    resolver_match = resolver.resolve(request.path_info)
  File "/server/software/pyenv/versions/2.7.5/lib/python2.7/site-packages/django/core/urlresolvers.py", line 366, in resolve
    for pattern in self.url_patterns:
  File "/server/software/pyenv/versions/2.7.5/lib/python2.7/site-packages/django/core/urlresolvers.py", line 402, in url_patterns
    patterns = getattr(self.urlconf_module, "urlpatterns", self.urlconf_module)
  File "/server/software/pyenv/versions/2.7.5/lib/python2.7/site-packages/django/core/urlresolvers.py", line 396, in urlconf_module
    self._urlconf_module = import_module(self.urlconf_name)
  File "/server/software/pyenv/versions/2.7.5/lib/python2.7/importlib/__init__.py", line 37, in import_module
    __import__(name)
  File "/server/software/OpManage/OpManage/urls.py", line 9, in <module>
    admin.autodiscover()
NameError: name 'admin' is not defined
2016-08-03 06:42:53,478 [Thread-6:140680577693440] [django.request:256] [base:handle_uncaught_exception] [ERROR]- Internal Server Error: /api/v1/
Traceback (most recent call last):
  File "/server/software/pyenv/versions/2.7.5/lib/python2.7/site-packages/django/core/handlers/base.py", line 119, in get_response
    resolver_match = resolver.resolve(request.path_info)
  File "/server/software/pyenv/versions/2.7.5/lib/python2.7/site-packages/django/core/urlresolvers.py", line 366, in resolve
    for pattern in self.url_patterns:
  File "/server/software/pyenv/versions/2.7.5/lib/python2.7/site-packages/django/core/urlresolvers.py", line 402, in url_patterns
    patterns = getattr(self.urlconf_module, "urlpatterns", self.urlconf_module)
  File "/server/software/pyenv/versions/2.7.5/lib/python2.7/site-packages/django/core/urlresolvers.py", line 396, in urlconf_module
    self._urlconf_module = import_module(self.urlconf_name)
  File "/server/software/pyenv/versions/2.7.5/lib/python2.7/importlib/__init__.py", line 37, in import_module
    __import__(name)
  File "/server/software/OpManage/OpManage/urls.py", line 8, in <module>
    admin.autodiscover()
NameError: name 'admin' is not defined
2016-08-03 06:42:54,669 [Thread-7:140680577693440] [django.request:256] [base:handle_uncaught_exception] [ERROR]- Internal Server Error: /api/v1/
Traceback (most recent call last):
  File "/server/software/pyenv/versions/2.7.5/lib/python2.7/site-packages/django/core/handlers/base.py", line 119, in get_response
    resolver_match = resolver.resolve(request.path_info)
  File "/server/software/pyenv/versions/2.7.5/lib/python2.7/site-packages/django/core/urlresolvers.py", line 366, in resolve
    for pattern in self.url_patterns:
  File "/server/software/pyenv/versions/2.7.5/lib/python2.7/site-packages/django/core/urlresolvers.py", line 402, in url_patterns
    patterns = getattr(self.urlconf_module, "urlpatterns", self.urlconf_module)
  File "/server/software/pyenv/versions/2.7.5/lib/python2.7/site-packages/django/core/urlresolvers.py", line 396, in urlconf_module
    self._urlconf_module = import_module(self.urlconf_name)
  File "/server/software/pyenv/versions/2.7.5/lib/python2.7/importlib/__init__.py", line 37, in import_module
    __import__(name)
  File "/server/software/OpManage/OpManage/urls.py", line 8, in <module>
    admin.autodiscover()
NameError: name 'admin' is not defined
2016-08-03 06:42:56,113 [Thread-8:140680577693440] [django.request:256] [base:handle_uncaught_exception] [ERROR]- Internal Server Error: /api/v1/
Traceback (most recent call last):
  File "/server/software/pyenv/versions/2.7.5/lib/python2.7/site-packages/django/core/handlers/base.py", line 119, in get_response
    resolver_match = resolver.resolve(request.path_info)
  File "/server/software/pyenv/versions/2.7.5/lib/python2.7/site-packages/django/core/urlresolvers.py", line 366, in resolve
    for pattern in self.url_patterns:
  File "/server/software/pyenv/versions/2.7.5/lib/python2.7/site-packages/django/core/urlresolvers.py", line 402, in url_patterns
    patterns = getattr(self.urlconf_module, "urlpatterns", self.urlconf_module)
  File "/server/software/pyenv/versions/2.7.5/lib/python2.7/site-packages/django/core/urlresolvers.py", line 396, in urlconf_module
    self._urlconf_module = import_module(self.urlconf_name)
  File "/server/software/pyenv/versions/2.7.5/lib/python2.7/importlib/__init__.py", line 37, in import_module
    __import__(name)
  File "/server/software/OpManage/OpManage/urls.py", line 8, in <module>
    admin.autodiscover()
NameError: name 'admin' is not defined
2016-08-03 06:42:56,875 [Thread-9:140680577693440] [django.request:256] [base:handle_uncaught_exception] [ERROR]- Internal Server Error: /api/v1/
Traceback (most recent call last):
  File "/server/software/pyenv/versions/2.7.5/lib/python2.7/site-packages/django/core/handlers/base.py", line 119, in get_response
    resolver_match = resolver.resolve(request.path_info)
  File "/server/software/pyenv/versions/2.7.5/lib/python2.7/site-packages/django/core/urlresolvers.py", line 366, in resolve
    for pattern in self.url_patterns:
  File "/server/software/pyenv/versions/2.7.5/lib/python2.7/site-packages/django/core/urlresolvers.py", line 402, in url_patterns
    patterns = getattr(self.urlconf_module, "urlpatterns", self.urlconf_module)
  File "/server/software/pyenv/versions/2.7.5/lib/python2.7/site-packages/django/core/urlresolvers.py", line 396, in urlconf_module
    self._urlconf_module = import_module(self.urlconf_name)
  File "/server/software/pyenv/versions/2.7.5/lib/python2.7/importlib/__init__.py", line 37, in import_module
    __import__(name)
  File "/server/software/OpManage/OpManage/urls.py", line 8, in <module>
    admin.autodiscover()
NameError: name 'admin' is not defined
2016-08-03 06:43:48,128 [Thread-10:140680577693440] [django.request:256] [base:handle_uncaught_exception] [ERROR]- Internal Server Error: /api/v1/
Traceback (most recent call last):
  File "/server/software/pyenv/versions/2.7.5/lib/python2.7/site-packages/django/core/handlers/base.py", line 119, in get_response
    resolver_match = resolver.resolve(request.path_info)
  File "/server/software/pyenv/versions/2.7.5/lib/python2.7/site-packages/django/core/urlresolvers.py", line 366, in resolve
    for pattern in self.url_patterns:
  File "/server/software/pyenv/versions/2.7.5/lib/python2.7/site-packages/django/core/urlresolvers.py", line 402, in url_patterns
    patterns = getattr(self.urlconf_module, "urlpatterns", self.urlconf_module)
  File "/server/software/pyenv/versions/2.7.5/lib/python2.7/site-packages/django/core/urlresolvers.py", line 396, in urlconf_module
    self._urlconf_module = import_module(self.urlconf_name)
  File "/server/software/pyenv/versions/2.7.5/lib/python2.7/importlib/__init__.py", line 37, in import_module
    __import__(name)
  File "/server/software/OpManage/OpManage/urls.py", line 8, in <module>
    admin.autodiscover()
NameError: name 'admin' is not defined
2016-08-03 06:43:49,260 [Thread-11:140680577693440] [django.request:256] [base:handle_uncaught_exception] [ERROR]- Internal Server Error: /api/v1/
Traceback (most recent call last):
  File "/server/software/pyenv/versions/2.7.5/lib/python2.7/site-packages/django/core/handlers/base.py", line 119, in get_response
    resolver_match = resolver.resolve(request.path_info)
  File "/server/software/pyenv/versions/2.7.5/lib/python2.7/site-packages/django/core/urlresolvers.py", line 366, in resolve
    for pattern in self.url_patterns:
  File "/server/software/pyenv/versions/2.7.5/lib/python2.7/site-packages/django/core/urlresolvers.py", line 402, in url_patterns
    patterns = getattr(self.urlconf_module, "urlpatterns", self.urlconf_module)
  File "/server/software/pyenv/versions/2.7.5/lib/python2.7/site-packages/django/core/urlresolvers.py", line 396, in urlconf_module
    self._urlconf_module = import_module(self.urlconf_name)
  File "/server/software/pyenv/versions/2.7.5/lib/python2.7/importlib/__init__.py", line 37, in import_module
    __import__(name)
  File "/server/software/OpManage/OpManage/urls.py", line 8, in <module>
    admin.autodiscover()
NameError: name 'admin' is not defined
2016-08-03 06:43:55,286 [Thread-2:139992781289216] [django.request:256] [base:handle_uncaught_exception] [ERROR]- Internal Server Error: /api/v1/
Traceback (most recent call last):
  File "/server/software/pyenv/versions/2.7.5/lib/python2.7/site-packages/django/core/handlers/base.py", line 119, in get_response
    resolver_match = resolver.resolve(request.path_info)
  File "/server/software/pyenv/versions/2.7.5/lib/python2.7/site-packages/django/core/urlresolvers.py", line 366, in resolve
    for pattern in self.url_patterns:
  File "/server/software/pyenv/versions/2.7.5/lib/python2.7/site-packages/django/core/urlresolvers.py", line 402, in url_patterns
    patterns = getattr(self.urlconf_module, "urlpatterns", self.urlconf_module)
  File "/server/software/pyenv/versions/2.7.5/lib/python2.7/site-packages/django/core/urlresolvers.py", line 396, in urlconf_module
    self._urlconf_module = import_module(self.urlconf_name)
  File "/server/software/pyenv/versions/2.7.5/lib/python2.7/importlib/__init__.py", line 37, in import_module
    __import__(name)
  File "/server/software/OpManage/OpManage/urls.py", line 8, in <module>
    admin.autodiscover()
NameError: name 'admin' is not defined
2016-08-03 06:44:18,420 [Thread-3:139992781289216] [django.request:256] [base:handle_uncaught_exception] [ERROR]- Internal Server Error: /api/v1/
Traceback (most recent call last):
  File "/server/software/pyenv/versions/2.7.5/lib/python2.7/site-packages/django/core/handlers/base.py", line 119, in get_response
    resolver_match = resolver.resolve(request.path_info)
  File "/server/software/pyenv/versions/2.7.5/lib/python2.7/site-packages/django/core/urlresolvers.py", line 366, in resolve
    for pattern in self.url_patterns:
  File "/server/software/pyenv/versions/2.7.5/lib/python2.7/site-packages/django/core/urlresolvers.py", line 402, in url_patterns
    patterns = getattr(self.urlconf_module, "urlpatterns", self.urlconf_module)
  File "/server/software/pyenv/versions/2.7.5/lib/python2.7/site-packages/django/core/urlresolvers.py", line 396, in urlconf_module
    self._urlconf_module = import_module(self.urlconf_name)
  File "/server/software/pyenv/versions/2.7.5/lib/python2.7/importlib/__init__.py", line 37, in import_module
    __import__(name)
  File "/server/software/OpManage/OpManage/urls.py", line 20, in <module>
    url(r'^admin/', include('django.contrib.admin.site.urls')),
  File "/server/software/pyenv/versions/2.7.5/lib/python2.7/site-packages/django/conf/urls/__init__.py", line 33, in include
    urlconf_module = import_module(urlconf_module)
  File "/server/software/pyenv/versions/2.7.5/lib/python2.7/importlib/__init__.py", line 37, in import_module
    __import__(name)
ImportError: No module named site.urls
2016-08-03 06:44:22,606 [Thread-4:139992781289216] [django.request:256] [base:handle_uncaught_exception] [ERROR]- Internal Server Error: /api/v1/
Traceback (most recent call last):
  File "/server/software/pyenv/versions/2.7.5/lib/python2.7/site-packages/django/core/handlers/base.py", line 119, in get_response
    resolver_match = resolver.resolve(request.path_info)
  File "/server/software/pyenv/versions/2.7.5/lib/python2.7/site-packages/django/core/urlresolvers.py", line 366, in resolve
    for pattern in self.url_patterns:
  File "/server/software/pyenv/versions/2.7.5/lib/python2.7/site-packages/django/core/urlresolvers.py", line 402, in url_patterns
    patterns = getattr(self.urlconf_module, "urlpatterns", self.urlconf_module)
  File "/server/software/pyenv/versions/2.7.5/lib/python2.7/site-packages/django/core/urlresolvers.py", line 396, in urlconf_module
    self._urlconf_module = import_module(self.urlconf_name)
  File "/server/software/pyenv/versions/2.7.5/lib/python2.7/importlib/__init__.py", line 37, in import_module
    __import__(name)
  File "/server/software/OpManage/OpManage/urls.py", line 20, in <module>
    url(r'^admin/', include('django.contrib.admin.site.urls')),
  File "/server/software/pyenv/versions/2.7.5/lib/python2.7/site-packages/django/conf/urls/__init__.py", line 33, in include
    urlconf_module = import_module(urlconf_module)
  File "/server/software/pyenv/versions/2.7.5/lib/python2.7/importlib/__init__.py", line 37, in import_module
    __import__(name)
ImportError: No module named site.urls
2016-08-03 06:44:23,701 [Thread-5:139992781289216] [django.request:256] [base:handle_uncaught_exception] [ERROR]- Internal Server Error: /api/v1/
Traceback (most recent call last):
  File "/server/software/pyenv/versions/2.7.5/lib/python2.7/site-packages/django/core/handlers/base.py", line 119, in get_response
    resolver_match = resolver.resolve(request.path_info)
  File "/server/software/pyenv/versions/2.7.5/lib/python2.7/site-packages/django/core/urlresolvers.py", line 366, in resolve
    for pattern in self.url_patterns:
  File "/server/software/pyenv/versions/2.7.5/lib/python2.7/site-packages/django/core/urlresolvers.py", line 402, in url_patterns
    patterns = getattr(self.urlconf_module, "urlpatterns", self.urlconf_module)
  File "/server/software/pyenv/versions/2.7.5/lib/python2.7/site-packages/django/core/urlresolvers.py", line 396, in urlconf_module
    self._urlconf_module = import_module(self.urlconf_name)
  File "/server/software/pyenv/versions/2.7.5/lib/python2.7/importlib/__init__.py", line 37, in import_module
    __import__(name)
  File "/server/software/OpManage/OpManage/urls.py", line 20, in <module>
    url(r'^admin/', include('django.contrib.admin.site.urls')),
  File "/server/software/pyenv/versions/2.7.5/lib/python2.7/site-packages/django/conf/urls/__init__.py", line 33, in include
    urlconf_module = import_module(urlconf_module)
  File "/server/software/pyenv/versions/2.7.5/lib/python2.7/importlib/__init__.py", line 37, in import_module
    __import__(name)
ImportError: No module named site.urls
2016-08-03 06:44:24,613 [Thread-6:139992781289216] [django.request:256] [base:handle_uncaught_exception] [ERROR]- Internal Server Error: /api/v1/
Traceback (most recent call last):
  File "/server/software/pyenv/versions/2.7.5/lib/python2.7/site-packages/django/core/handlers/base.py", line 119, in get_response
    resolver_match = resolver.resolve(request.path_info)
  File "/server/software/pyenv/versions/2.7.5/lib/python2.7/site-packages/django/core/urlresolvers.py", line 366, in resolve
    for pattern in self.url_patterns:
  File "/server/software/pyenv/versions/2.7.5/lib/python2.7/site-packages/django/core/urlresolvers.py", line 402, in url_patterns
    patterns = getattr(self.urlconf_module, "urlpatterns", self.urlconf_module)
  File "/server/software/pyenv/versions/2.7.5/lib/python2.7/site-packages/django/core/urlresolvers.py", line 396, in urlconf_module
    self._urlconf_module = import_module(self.urlconf_name)
  File "/server/software/pyenv/versions/2.7.5/lib/python2.7/importlib/__init__.py", line 37, in import_module
    __import__(name)
  File "/server/software/OpManage/OpManage/urls.py", line 20, in <module>
    url(r'^admin/', include('django.contrib.admin.site.urls')),
  File "/server/software/pyenv/versions/2.7.5/lib/python2.7/site-packages/django/conf/urls/__init__.py", line 33, in include
    urlconf_module = import_module(urlconf_module)
  File "/server/software/pyenv/versions/2.7.5/lib/python2.7/importlib/__init__.py", line 37, in import_module
    __import__(name)
ImportError: No module named site.urls
2016-08-03 06:44:25,367 [Thread-7:139992781289216] [django.request:256] [base:handle_uncaught_exception] [ERROR]- Internal Server Error: /api/v1/
Traceback (most recent call last):
  File "/server/software/pyenv/versions/2.7.5/lib/python2.7/site-packages/django/core/handlers/base.py", line 119, in get_response
    resolver_match = resolver.resolve(request.path_info)
  File "/server/software/pyenv/versions/2.7.5/lib/python2.7/site-packages/django/core/urlresolvers.py", line 366, in resolve
    for pattern in self.url_patterns:
  File "/server/software/pyenv/versions/2.7.5/lib/python2.7/site-packages/django/core/urlresolvers.py", line 402, in url_patterns
    patterns = getattr(self.urlconf_module, "urlpatterns", self.urlconf_module)
  File "/server/software/pyenv/versions/2.7.5/lib/python2.7/site-packages/django/core/urlresolvers.py", line 396, in urlconf_module
    self._urlconf_module = import_module(self.urlconf_name)
  File "/server/software/pyenv/versions/2.7.5/lib/python2.7/importlib/__init__.py", line 37, in import_module
    __import__(name)
  File "/server/software/OpManage/OpManage/urls.py", line 20, in <module>
    url(r'^admin/', include('django.contrib.admin.site.urls')),
  File "/server/software/pyenv/versions/2.7.5/lib/python2.7/site-packages/django/conf/urls/__init__.py", line 33, in include
    urlconf_module = import_module(urlconf_module)
  File "/server/software/pyenv/versions/2.7.5/lib/python2.7/importlib/__init__.py", line 37, in import_module
    __import__(name)
ImportError: No module named site.urls
2016-08-03 06:44:26,118 [Thread-8:139992781289216] [django.request:256] [base:handle_uncaught_exception] [ERROR]- Internal Server Error: /api/v1/
Traceback (most recent call last):
  File "/server/software/pyenv/versions/2.7.5/lib/python2.7/site-packages/django/core/handlers/base.py", line 119, in get_response
    resolver_match = resolver.resolve(request.path_info)
  File "/server/software/pyenv/versions/2.7.5/lib/python2.7/site-packages/django/core/urlresolvers.py", line 366, in resolve
    for pattern in self.url_patterns:
  File "/server/software/pyenv/versions/2.7.5/lib/python2.7/site-packages/django/core/urlresolvers.py", line 402, in url_patterns
    patterns = getattr(self.urlconf_module, "urlpatterns", self.urlconf_module)
  File "/server/software/pyenv/versions/2.7.5/lib/python2.7/site-packages/django/core/urlresolvers.py", line 396, in urlconf_module
    self._urlconf_module = import_module(self.urlconf_name)
  File "/server/software/pyenv/versions/2.7.5/lib/python2.7/importlib/__init__.py", line 37, in import_module
    __import__(name)
  File "/server/software/OpManage/OpManage/urls.py", line 20, in <module>
    url(r'^admin/', include('django.contrib.admin.site.urls')),
  File "/server/software/pyenv/versions/2.7.5/lib/python2.7/site-packages/django/conf/urls/__init__.py", line 33, in include
    urlconf_module = import_module(urlconf_module)
  File "/server/software/pyenv/versions/2.7.5/lib/python2.7/importlib/__init__.py", line 37, in import_module
    __import__(name)
ImportError: No module named site.urls
2016-08-03 06:44:26,778 [Thread-9:139992781289216] [django.request:256] [base:handle_uncaught_exception] [ERROR]- Internal Server Error: /api/v1/
Traceback (most recent call last):
  File "/server/software/pyenv/versions/2.7.5/lib/python2.7/site-packages/django/core/handlers/base.py", line 119, in get_response
    resolver_match = resolver.resolve(request.path_info)
  File "/server/software/pyenv/versions/2.7.5/lib/python2.7/site-packages/django/core/urlresolvers.py", line 366, in resolve
    for pattern in self.url_patterns:
  File "/server/software/pyenv/versions/2.7.5/lib/python2.7/site-packages/django/core/urlresolvers.py", line 402, in url_patterns
    patterns = getattr(self.urlconf_module, "urlpatterns", self.urlconf_module)
  File "/server/software/pyenv/versions/2.7.5/lib/python2.7/site-packages/django/core/urlresolvers.py", line 396, in urlconf_module
    self._urlconf_module = import_module(self.urlconf_name)
  File "/server/software/pyenv/versions/2.7.5/lib/python2.7/importlib/__init__.py", line 37, in import_module
    __import__(name)
  File "/server/software/OpManage/OpManage/urls.py", line 20, in <module>
    url(r'^admin/', include('django.contrib.admin.site.urls')),
  File "/server/software/pyenv/versions/2.7.5/lib/python2.7/site-packages/django/conf/urls/__init__.py", line 33, in include
    urlconf_module = import_module(urlconf_module)
  File "/server/software/pyenv/versions/2.7.5/lib/python2.7/importlib/__init__.py", line 37, in import_module
    __import__(name)
ImportError: No module named site.urls
2016-08-03 06:44:27,239 [Thread-10:139992781289216] [django.request:256] [base:handle_uncaught_exception] [ERROR]- Internal Server Error: /api/v1/
Traceback (most recent call last):
  File "/server/software/pyenv/versions/2.7.5/lib/python2.7/site-packages/django/core/handlers/base.py", line 119, in get_response
    resolver_match = resolver.resolve(request.path_info)
  File "/server/software/pyenv/versions/2.7.5/lib/python2.7/site-packages/django/core/urlresolvers.py", line 366, in resolve
    for pattern in self.url_patterns:
  File "/server/software/pyenv/versions/2.7.5/lib/python2.7/site-packages/django/core/urlresolvers.py", line 402, in url_patterns
    patterns = getattr(self.urlconf_module, "urlpatterns", self.urlconf_module)
  File "/server/software/pyenv/versions/2.7.5/lib/python2.7/site-packages/django/core/urlresolvers.py", line 396, in urlconf_module
    self._urlconf_module = import_module(self.urlconf_name)
  File "/server/software/pyenv/versions/2.7.5/lib/python2.7/importlib/__init__.py", line 37, in import_module
    __import__(name)
  File "/server/software/OpManage/OpManage/urls.py", line 20, in <module>
    url(r'^admin/', include('django.contrib.admin.site.urls')),
  File "/server/software/pyenv/versions/2.7.5/lib/python2.7/site-packages/django/conf/urls/__init__.py", line 33, in include
    urlconf_module = import_module(urlconf_module)
  File "/server/software/pyenv/versions/2.7.5/lib/python2.7/importlib/__init__.py", line 37, in import_module
    __import__(name)
ImportError: No module named site.urls
2016-08-03 06:44:27,740 [Thread-11:139992781289216] [django.request:256] [base:handle_uncaught_exception] [ERROR]- Internal Server Error: /api/v1/
Traceback (most recent call last):
  File "/server/software/pyenv/versions/2.7.5/lib/python2.7/site-packages/django/core/handlers/base.py", line 119, in get_response
    resolver_match = resolver.resolve(request.path_info)
  File "/server/software/pyenv/versions/2.7.5/lib/python2.7/site-packages/django/core/urlresolvers.py", line 366, in resolve
    for pattern in self.url_patterns:
  File "/server/software/pyenv/versions/2.7.5/lib/python2.7/site-packages/django/core/urlresolvers.py", line 402, in url_patterns
    patterns = getattr(self.urlconf_module, "urlpatterns", self.urlconf_module)
  File "/server/software/pyenv/versions/2.7.5/lib/python2.7/site-packages/django/core/urlresolvers.py", line 396, in urlconf_module
    self._urlconf_module = import_module(self.urlconf_name)
  File "/server/software/pyenv/versions/2.7.5/lib/python2.7/importlib/__init__.py", line 37, in import_module
    __import__(name)
  File "/server/software/OpManage/OpManage/urls.py", line 20, in <module>
    url(r'^admin/', include('django.contrib.admin.site.urls')),
  File "/server/software/pyenv/versions/2.7.5/lib/python2.7/site-packages/django/conf/urls/__init__.py", line 33, in include
    urlconf_module = import_module(urlconf_module)
  File "/server/software/pyenv/versions/2.7.5/lib/python2.7/importlib/__init__.py", line 37, in import_module
    __import__(name)
ImportError: No module named site.urls
2016-08-03 06:44:28,223 [Thread-12:139992781289216] [django.request:256] [base:handle_uncaught_exception] [ERROR]- Internal Server Error: /api/v1/
Traceback (most recent call last):
  File "/server/software/pyenv/versions/2.7.5/lib/python2.7/site-packages/django/core/handlers/base.py", line 119, in get_response
    resolver_match = resolver.resolve(request.path_info)
  File "/server/software/pyenv/versions/2.7.5/lib/python2.7/site-packages/django/core/urlresolvers.py", line 366, in resolve
    for pattern in self.url_patterns:
  File "/server/software/pyenv/versions/2.7.5/lib/python2.7/site-packages/django/core/urlresolvers.py", line 402, in url_patterns
    patterns = getattr(self.urlconf_module, "urlpatterns", self.urlconf_module)
  File "/server/software/pyenv/versions/2.7.5/lib/python2.7/site-packages/django/core/urlresolvers.py", line 396, in urlconf_module
    self._urlconf_module = import_module(self.urlconf_name)
  File "/server/software/pyenv/versions/2.7.5/lib/python2.7/importlib/__init__.py", line 37, in import_module
    __import__(name)
  File "/server/software/OpManage/OpManage/urls.py", line 20, in <module>
    url(r'^admin/', include('django.contrib.admin.site.urls')),
  File "/server/software/pyenv/versions/2.7.5/lib/python2.7/site-packages/django/conf/urls/__init__.py", line 33, in include
    urlconf_module = import_module(urlconf_module)
  File "/server/software/pyenv/versions/2.7.5/lib/python2.7/importlib/__init__.py", line 37, in import_module
    __import__(name)
ImportError: No module named site.urls
2016-08-03 06:44:30,900 [Thread-13:139992781289216] [django.request:256] [base:handle_uncaught_exception] [ERROR]- Internal Server Error: /api/v1/
Traceback (most recent call last):
  File "/server/software/pyenv/versions/2.7.5/lib/python2.7/site-packages/django/core/handlers/base.py", line 119, in get_response
    resolver_match = resolver.resolve(request.path_info)
  File "/server/software/pyenv/versions/2.7.5/lib/python2.7/site-packages/django/core/urlresolvers.py", line 366, in resolve
    for pattern in self.url_patterns:
  File "/server/software/pyenv/versions/2.7.5/lib/python2.7/site-packages/django/core/urlresolvers.py", line 402, in url_patterns
    patterns = getattr(self.urlconf_module, "urlpatterns", self.urlconf_module)
  File "/server/software/pyenv/versions/2.7.5/lib/python2.7/site-packages/django/core/urlresolvers.py", line 396, in urlconf_module
    self._urlconf_module = import_module(self.urlconf_name)
  File "/server/software/pyenv/versions/2.7.5/lib/python2.7/importlib/__init__.py", line 37, in import_module
    __import__(name)
  File "/server/software/OpManage/OpManage/urls.py", line 20, in <module>
    url(r'^admin/', include('django.contrib.admin.site.urls')),
  File "/server/software/pyenv/versions/2.7.5/lib/python2.7/site-packages/django/conf/urls/__init__.py", line 33, in include
    urlconf_module = import_module(urlconf_module)
  File "/server/software/pyenv/versions/2.7.5/lib/python2.7/importlib/__init__.py", line 37, in import_module
    __import__(name)
ImportError: No module named site.urls
2016-08-03 06:44:32,324 [Thread-14:139992781289216] [django.request:256] [base:handle_uncaught_exception] [ERROR]- Internal Server Error: /api/v1/
Traceback (most recent call last):
  File "/server/software/pyenv/versions/2.7.5/lib/python2.7/site-packages/django/core/handlers/base.py", line 119, in get_response
    resolver_match = resolver.resolve(request.path_info)
  File "/server/software/pyenv/versions/2.7.5/lib/python2.7/site-packages/django/core/urlresolvers.py", line 366, in resolve
    for pattern in self.url_patterns:
  File "/server/software/pyenv/versions/2.7.5/lib/python2.7/site-packages/django/core/urlresolvers.py", line 402, in url_patterns
    patterns = getattr(self.urlconf_module, "urlpatterns", self.urlconf_module)
  File "/server/software/pyenv/versions/2.7.5/lib/python2.7/site-packages/django/core/urlresolvers.py", line 396, in urlconf_module
    self._urlconf_module = import_module(self.urlconf_name)
  File "/server/software/pyenv/versions/2.7.5/lib/python2.7/importlib/__init__.py", line 37, in import_module
    __import__(name)
  File "/server/software/OpManage/OpManage/urls.py", line 20, in <module>
    url(r'^admin/', include('django.contrib.admin.site.urls')),
  File "/server/software/pyenv/versions/2.7.5/lib/python2.7/site-packages/django/conf/urls/__init__.py", line 33, in include
    urlconf_module = import_module(urlconf_module)
  File "/server/software/pyenv/versions/2.7.5/lib/python2.7/importlib/__init__.py", line 37, in import_module
    __import__(name)
ImportError: No module named site.urls
2016-08-03 06:44:33,098 [Thread-15:139992781289216] [django.request:256] [base:handle_uncaught_exception] [ERROR]- Internal Server Error: /api/v1/
Traceback (most recent call last):
  File "/server/software/pyenv/versions/2.7.5/lib/python2.7/site-packages/django/core/handlers/base.py", line 119, in get_response
    resolver_match = resolver.resolve(request.path_info)
  File "/server/software/pyenv/versions/2.7.5/lib/python2.7/site-packages/django/core/urlresolvers.py", line 366, in resolve
    for pattern in self.url_patterns:
  File "/server/software/pyenv/versions/2.7.5/lib/python2.7/site-packages/django/core/urlresolvers.py", line 402, in url_patterns
    patterns = getattr(self.urlconf_module, "urlpatterns", self.urlconf_module)
  File "/server/software/pyenv/versions/2.7.5/lib/python2.7/site-packages/django/core/urlresolvers.py", line 396, in urlconf_module
    self._urlconf_module = import_module(self.urlconf_name)
  File "/server/software/pyenv/versions/2.7.5/lib/python2.7/importlib/__init__.py", line 37, in import_module
    __import__(name)
  File "/server/software/OpManage/OpManage/urls.py", line 20, in <module>
    url(r'^admin/', include('django.contrib.admin.site.urls')),
  File "/server/software/pyenv/versions/2.7.5/lib/python2.7/site-packages/django/conf/urls/__init__.py", line 33, in include
    urlconf_module = import_module(urlconf_module)
  File "/server/software/pyenv/versions/2.7.5/lib/python2.7/importlib/__init__.py", line 37, in import_module
    __import__(name)
ImportError: No module named site.urls
2016-08-03 06:44:33,600 [Thread-16:139992781289216] [django.request:256] [base:handle_uncaught_exception] [ERROR]- Internal Server Error: /api/v1/
Traceback (most recent call last):
  File "/server/software/pyenv/versions/2.7.5/lib/python2.7/site-packages/django/core/handlers/base.py", line 119, in get_response
    resolver_match = resolver.resolve(request.path_info)
  File "/server/software/pyenv/versions/2.7.5/lib/python2.7/site-packages/django/core/urlresolvers.py", line 366, in resolve
    for pattern in self.url_patterns:
  File "/server/software/pyenv/versions/2.7.5/lib/python2.7/site-packages/django/core/urlresolvers.py", line 402, in url_patterns
    patterns = getattr(self.urlconf_module, "urlpatterns", self.urlconf_module)
  File "/server/software/pyenv/versions/2.7.5/lib/python2.7/site-packages/django/core/urlresolvers.py", line 396, in urlconf_module
    self._urlconf_module = import_module(self.urlconf_name)
  File "/server/software/pyenv/versions/2.7.5/lib/python2.7/importlib/__init__.py", line 37, in import_module
    __import__(name)
  File "/server/software/OpManage/OpManage/urls.py", line 20, in <module>
    url(r'^admin/', include('django.contrib.admin.site.urls')),
  File "/server/software/pyenv/versions/2.7.5/lib/python2.7/site-packages/django/conf/urls/__init__.py", line 33, in include
    urlconf_module = import_module(urlconf_module)
  File "/server/software/pyenv/versions/2.7.5/lib/python2.7/importlib/__init__.py", line 37, in import_module
    __import__(name)
ImportError: No module named site.urls
2016-08-03 06:44:33,725 [Thread-17:139992770799360] [django.request:256] [base:handle_uncaught_exception] [ERROR]- Internal Server Error: /api/v1/
Traceback (most recent call last):
  File "/server/software/pyenv/versions/2.7.5/lib/python2.7/site-packages/django/core/handlers/base.py", line 119, in get_response
    resolver_match = resolver.resolve(request.path_info)
  File "/server/software/pyenv/versions/2.7.5/lib/python2.7/site-packages/django/core/urlresolvers.py", line 366, in resolve
    for pattern in self.url_patterns:
  File "/server/software/pyenv/versions/2.7.5/lib/python2.7/site-packages/django/core/urlresolvers.py", line 402, in url_patterns
    patterns = getattr(self.urlconf_module, "urlpatterns", self.urlconf_module)
  File "/server/software/pyenv/versions/2.7.5/lib/python2.7/site-packages/django/core/urlresolvers.py", line 396, in urlconf_module
    self._urlconf_module = import_module(self.urlconf_name)
  File "/server/software/pyenv/versions/2.7.5/lib/python2.7/importlib/__init__.py", line 37, in import_module
    __import__(name)
  File "/server/software/OpManage/OpManage/urls.py", line 20, in <module>
    url(r'^admin/', include('django.contrib.admin.site.urls')),
  File "/server/software/pyenv/versions/2.7.5/lib/python2.7/site-packages/django/conf/urls/__init__.py", line 33, in include
    urlconf_module = import_module(urlconf_module)
  File "/server/software/pyenv/versions/2.7.5/lib/python2.7/importlib/__init__.py", line 37, in import_module
    __import__(name)
ImportError: No module named site.urls
2016-08-03 06:44:33,826 [Thread-18:139992770799360] [django.request:256] [base:handle_uncaught_exception] [ERROR]- Internal Server Error: /api/v1/
Traceback (most recent call last):
  File "/server/software/pyenv/versions/2.7.5/lib/python2.7/site-packages/django/core/handlers/base.py", line 119, in get_response
    resolver_match = resolver.resolve(request.path_info)
  File "/server/software/pyenv/versions/2.7.5/lib/python2.7/site-packages/django/core/urlresolvers.py", line 366, in resolve
    for pattern in self.url_patterns:
  File "/server/software/pyenv/versions/2.7.5/lib/python2.7/site-packages/django/core/urlresolvers.py", line 402, in url_patterns
    patterns = getattr(self.urlconf_module, "urlpatterns", self.urlconf_module)
  File "/server/software/pyenv/versions/2.7.5/lib/python2.7/site-packages/django/core/urlresolvers.py", line 396, in urlconf_module
    self._urlconf_module = import_module(self.urlconf_name)
  File "/server/software/pyenv/versions/2.7.5/lib/python2.7/importlib/__init__.py", line 37, in import_module
    __import__(name)
  File "/server/software/OpManage/OpManage/urls.py", line 20, in <module>
    url(r'^admin/', include('django.contrib.admin.site.urls')),
  File "/server/software/pyenv/versions/2.7.5/lib/python2.7/site-packages/django/conf/urls/__init__.py", line 33, in include
    urlconf_module = import_module(urlconf_module)
  File "/server/software/pyenv/versions/2.7.5/lib/python2.7/importlib/__init__.py", line 37, in import_module
    __import__(name)
ImportError: No module named site.urls
2016-08-03 06:44:34,762 [Thread-19:139992770799360] [django.request:256] [base:handle_uncaught_exception] [ERROR]- Internal Server Error: /api/v1/
Traceback (most recent call last):
  File "/server/software/pyenv/versions/2.7.5/lib/python2.7/site-packages/django/core/handlers/base.py", line 119, in get_response
    resolver_match = resolver.resolve(request.path_info)
  File "/server/software/pyenv/versions/2.7.5/lib/python2.7/site-packages/django/core/urlresolvers.py", line 366, in resolve
    for pattern in self.url_patterns:
  File "/server/software/pyenv/versions/2.7.5/lib/python2.7/site-packages/django/core/urlresolvers.py", line 402, in url_patterns
    patterns = getattr(self.urlconf_module, "urlpatterns", self.urlconf_module)
  File "/server/software/pyenv/versions/2.7.5/lib/python2.7/site-packages/django/core/urlresolvers.py", line 396, in urlconf_module
    self._urlconf_module = import_module(self.urlconf_name)
  File "/server/software/pyenv/versions/2.7.5/lib/python2.7/importlib/__init__.py", line 37, in import_module
    __import__(name)
  File "/server/software/OpManage/OpManage/urls.py", line 20, in <module>
    url(r'^admin/', include('django.contrib.admin.site.urls')),
  File "/server/software/pyenv/versions/2.7.5/lib/python2.7/site-packages/django/conf/urls/__init__.py", line 33, in include
    urlconf_module = import_module(urlconf_module)
  File "/server/software/pyenv/versions/2.7.5/lib/python2.7/importlib/__init__.py", line 37, in import_module
    __import__(name)
ImportError: No module named site.urls
2016-08-03 06:44:58,653 [Thread-20:139992770799360] [django.request:256] [base:handle_uncaught_exception] [ERROR]- Internal Server Error: /api/v1/
Traceback (most recent call last):
  File "/server/software/pyenv/versions/2.7.5/lib/python2.7/site-packages/django/core/handlers/base.py", line 119, in get_response
    resolver_match = resolver.resolve(request.path_info)
  File "/server/software/pyenv/versions/2.7.5/lib/python2.7/site-packages/django/core/urlresolvers.py", line 366, in resolve
    for pattern in self.url_patterns:
  File "/server/software/pyenv/versions/2.7.5/lib/python2.7/site-packages/django/core/urlresolvers.py", line 402, in url_patterns
    patterns = getattr(self.urlconf_module, "urlpatterns", self.urlconf_module)
  File "/server/software/pyenv/versions/2.7.5/lib/python2.7/site-packages/django/core/urlresolvers.py", line 396, in urlconf_module
    self._urlconf_module = import_module(self.urlconf_name)
  File "/server/software/pyenv/versions/2.7.5/lib/python2.7/importlib/__init__.py", line 37, in import_module
    __import__(name)
  File "/server/software/OpManage/OpManage/urls.py", line 20, in <module>
    url(r'^admin/', include('django.contrib.admin.site.urls')),
  File "/server/software/pyenv/versions/2.7.5/lib/python2.7/site-packages/django/conf/urls/__init__.py", line 33, in include
    urlconf_module = import_module(urlconf_module)
  File "/server/software/pyenv/versions/2.7.5/lib/python2.7/importlib/__init__.py", line 37, in import_module
    __import__(name)
ImportError: No module named site.urls
2016-08-03 06:45:12,015 [Thread-21:139992770799360] [django.request:256] [base:handle_uncaught_exception] [ERROR]- Internal Server Error: /api/v1/
Traceback (most recent call last):
  File "/server/software/pyenv/versions/2.7.5/lib/python2.7/site-packages/django/core/handlers/base.py", line 119, in get_response
    resolver_match = resolver.resolve(request.path_info)
  File "/server/software/pyenv/versions/2.7.5/lib/python2.7/site-packages/django/core/urlresolvers.py", line 366, in resolve
    for pattern in self.url_patterns:
  File "/server/software/pyenv/versions/2.7.5/lib/python2.7/site-packages/django/core/urlresolvers.py", line 402, in url_patterns
    patterns = getattr(self.urlconf_module, "urlpatterns", self.urlconf_module)
  File "/server/software/pyenv/versions/2.7.5/lib/python2.7/site-packages/django/core/urlresolvers.py", line 396, in urlconf_module
    self._urlconf_module = import_module(self.urlconf_name)
  File "/server/software/pyenv/versions/2.7.5/lib/python2.7/importlib/__init__.py", line 37, in import_module
    __import__(name)
  File "/server/software/OpManage/OpManage/urls.py", line 20, in <module>
    url(r'^admin/', include('admin.site.urls')),
  File "/server/software/pyenv/versions/2.7.5/lib/python2.7/site-packages/django/conf/urls/__init__.py", line 33, in include
    urlconf_module = import_module(urlconf_module)
  File "/server/software/pyenv/versions/2.7.5/lib/python2.7/importlib/__init__.py", line 37, in import_module
    __import__(name)
ImportError: No module named admin.site.urls
2016-08-03 07:01:04,870 [Thread-14:140081055659776] [django.request:170] [base:get_response] [WARNING]- Not Found: /api/v1/users
2016-08-03 07:01:10,595 [Thread-15:140081055659776] [django.request:170] [base:get_response] [WARNING]- Not Found: /api/v1/users
2016-08-03 07:01:24,855 [Thread-20:140081055659776] [django.request:170] [base:get_response] [WARNING]- Not Found: /api/v1/snippets/9
2016-08-03 07:22:02,942 [Thread-16:140706525906688] [django.request:170] [base:get_response] [WARNING]- Not Found: /api/v1/qweqweqweq
2016-08-03 15:47:26,589 [Thread-14:139788078274304] [django.request:170] [base:get_response] [WARNING]- Not Found: /api/v1/s
2016-08-03 15:47:42,754 [Thread-16:139788078274304] [django.request:170] [base:get_response] [WARNING]- Not Found: /api/v1/snippets
2016-08-03 15:49:01,720 [Thread-2:140263630509824] [django.request:256] [base:handle_uncaught_exception] [ERROR]- Internal Server Error: /api/v1/snippets
Traceback (most recent call last):
  File "/server/software/pyenv/versions/2.7.5/lib/python2.7/site-packages/django/core/handlers/base.py", line 108, in get_response
    response = middleware_method(request)
  File "/server/software/pyenv/versions/2.7.5/lib/python2.7/site-packages/django/middleware/common.py", line 74, in process_request
    if (not urlresolvers.is_valid_path(request.path_info, urlconf) and
  File "/server/software/pyenv/versions/2.7.5/lib/python2.7/site-packages/django/core/urlresolvers.py", line 647, in is_valid_path
    resolve(path, urlconf)
  File "/server/software/pyenv/versions/2.7.5/lib/python2.7/site-packages/django/core/urlresolvers.py", line 522, in resolve
    return get_resolver(urlconf).resolve(path)
  File "/server/software/pyenv/versions/2.7.5/lib/python2.7/site-packages/django/core/urlresolvers.py", line 366, in resolve
    for pattern in self.url_patterns:
  File "/server/software/pyenv/versions/2.7.5/lib/python2.7/site-packages/django/core/urlresolvers.py", line 402, in url_patterns
    patterns = getattr(self.urlconf_module, "urlpatterns", self.urlconf_module)
  File "/server/software/pyenv/versions/2.7.5/lib/python2.7/site-packages/django/core/urlresolvers.py", line 396, in urlconf_module
    self._urlconf_module = import_module(self.urlconf_name)
  File "/server/software/pyenv/versions/2.7.5/lib/python2.7/importlib/__init__.py", line 37, in import_module
    __import__(name)
  File "/server/software/OpManage/OpManage/urls.py", line 27, in <module>
    url(r'^api/v1/',include('Api.urls')), #settings中注册app后使用单引号不需要import
  File "/server/software/pyenv/versions/2.7.5/lib/python2.7/site-packages/django/conf/urls/__init__.py", line 33, in include
    urlconf_module = import_module(urlconf_module)
  File "/server/software/pyenv/versions/2.7.5/lib/python2.7/importlib/__init__.py", line 37, in import_module
    __import__(name)
  File "/server/software/OpManage/Api/urls.py", line 12, in <module>
    from Api.views import *
  File "/server/software/OpManage/Api/views.py", line 49
    "
    ^
SyntaxError: EOL while scanning string literal
2016-08-03 15:49:14,953 [Thread-3:140263630509824] [django.request:256] [base:handle_uncaught_exception] [ERROR]- Internal Server Error: /api/v1/snippets/
Traceback (most recent call last):
  File "/server/software/pyenv/versions/2.7.5/lib/python2.7/site-packages/django/core/handlers/base.py", line 119, in get_response
    resolver_match = resolver.resolve(request.path_info)
  File "/server/software/pyenv/versions/2.7.5/lib/python2.7/site-packages/django/core/urlresolvers.py", line 366, in resolve
    for pattern in self.url_patterns:
  File "/server/software/pyenv/versions/2.7.5/lib/python2.7/site-packages/django/core/urlresolvers.py", line 402, in url_patterns
    patterns = getattr(self.urlconf_module, "urlpatterns", self.urlconf_module)
  File "/server/software/pyenv/versions/2.7.5/lib/python2.7/site-packages/django/core/urlresolvers.py", line 396, in urlconf_module
    self._urlconf_module = import_module(self.urlconf_name)
  File "/server/software/pyenv/versions/2.7.5/lib/python2.7/importlib/__init__.py", line 37, in import_module
    __import__(name)
  File "/server/software/OpManage/OpManage/urls.py", line 27, in <module>
    url(r'^api/v1/',include('Api.urls')), #settings中注册app后使用单引号不需要import
  File "/server/software/pyenv/versions/2.7.5/lib/python2.7/site-packages/django/conf/urls/__init__.py", line 33, in include
    urlconf_module = import_module(urlconf_module)
  File "/server/software/pyenv/versions/2.7.5/lib/python2.7/importlib/__init__.py", line 37, in import_module
    __import__(name)
  File "/server/software/OpManage/Api/urls.py", line 12, in <module>
    from Api.views import *
  File "/server/software/OpManage/Api/views.py", line 49
    "
    ^
SyntaxError: EOL while scanning string literal
2016-08-03 15:49:17,114 [Thread-4:140263630509824] [django.request:256] [base:handle_uncaught_exception] [ERROR]- Internal Server Error: /api/v1/
Traceback (most recent call last):
  File "/server/software/pyenv/versions/2.7.5/lib/python2.7/site-packages/django/core/handlers/base.py", line 119, in get_response
    resolver_match = resolver.resolve(request.path_info)
  File "/server/software/pyenv/versions/2.7.5/lib/python2.7/site-packages/django/core/urlresolvers.py", line 366, in resolve
    for pattern in self.url_patterns:
  File "/server/software/pyenv/versions/2.7.5/lib/python2.7/site-packages/django/core/urlresolvers.py", line 402, in url_patterns
    patterns = getattr(self.urlconf_module, "urlpatterns", self.urlconf_module)
  File "/server/software/pyenv/versions/2.7.5/lib/python2.7/site-packages/django/core/urlresolvers.py", line 396, in urlconf_module
    self._urlconf_module = import_module(self.urlconf_name)
  File "/server/software/pyenv/versions/2.7.5/lib/python2.7/importlib/__init__.py", line 37, in import_module
    __import__(name)
  File "/server/software/OpManage/OpManage/urls.py", line 27, in <module>
    url(r'^api/v1/',include('Api.urls')), #settings中注册app后使用单引号不需要import
  File "/server/software/pyenv/versions/2.7.5/lib/python2.7/site-packages/django/conf/urls/__init__.py", line 33, in include
    urlconf_module = import_module(urlconf_module)
  File "/server/software/pyenv/versions/2.7.5/lib/python2.7/importlib/__init__.py", line 37, in import_module
    __import__(name)
  File "/server/software/OpManage/Api/urls.py", line 12, in <module>
    from Api.views import *
  File "/server/software/OpManage/Api/views.py", line 49
    "
    ^
SyntaxError: EOL while scanning string literal
2016-08-03 15:51:57,389 [Thread-52:140681016223488] [django.request:170] [base:get_response] [WARNING]- Not Found: /api/v1/snippets/8
2016-08-03 15:52:03,104 [Thread-53:140681016223488] [django.request:170] [base:get_response] [WARNING]- Not Found: /api/v1/snippets
2016-08-03 15:52:13,272 [Thread-56:140681016223488] [django.request:170] [base:get_response] [WARNING]- Not Found: /api/v1/snippets
2016-08-03 15:52:48,249 [Thread-2:140399039371008] [django.request:256] [base:handle_uncaught_exception] [ERROR]- Internal Server Error: /api/v1/snippets
Traceback (most recent call last):
  File "/server/software/pyenv/versions/2.7.5/lib/python2.7/site-packages/django/core/handlers/base.py", line 108, in get_response
    response = middleware_method(request)
  File "/server/software/pyenv/versions/2.7.5/lib/python2.7/site-packages/django/middleware/common.py", line 74, in process_request
    if (not urlresolvers.is_valid_path(request.path_info, urlconf) and
  File "/server/software/pyenv/versions/2.7.5/lib/python2.7/site-packages/django/core/urlresolvers.py", line 647, in is_valid_path
    resolve(path, urlconf)
  File "/server/software/pyenv/versions/2.7.5/lib/python2.7/site-packages/django/core/urlresolvers.py", line 522, in resolve
    return get_resolver(urlconf).resolve(path)
  File "/server/software/pyenv/versions/2.7.5/lib/python2.7/site-packages/django/core/urlresolvers.py", line 366, in resolve
    for pattern in self.url_patterns:
  File "/server/software/pyenv/versions/2.7.5/lib/python2.7/site-packages/django/core/urlresolvers.py", line 402, in url_patterns
    patterns = getattr(self.urlconf_module, "urlpatterns", self.urlconf_module)
  File "/server/software/pyenv/versions/2.7.5/lib/python2.7/site-packages/django/core/urlresolvers.py", line 396, in urlconf_module
    self._urlconf_module = import_module(self.urlconf_name)
  File "/server/software/pyenv/versions/2.7.5/lib/python2.7/importlib/__init__.py", line 37, in import_module
    __import__(name)
  File "/server/software/OpManage/OpManage/urls.py", line 27, in <module>
    url(r'^api/v1/',include('Api.urls')), #settings中注册app后使用单引号不需要import
  File "/server/software/pyenv/versions/2.7.5/lib/python2.7/site-packages/django/conf/urls/__init__.py", line 33, in include
    urlconf_module = import_module(urlconf_module)
  File "/server/software/pyenv/versions/2.7.5/lib/python2.7/importlib/__init__.py", line 37, in import_module
    __import__(name)
  File "/server/software/OpManage/Api/urls.py", line 12, in <module>
    from Api.views import *
  File "/server/software/OpManage/Api/views.py", line 44
    """
    查看、编辑组的界面
    """
      
                               
       ^
IndentationError: expected an indented block
2016-08-03 15:56:20,687 [Thread-3:140399039371008] [django.request:256] [base:handle_uncaught_exception] [ERROR]- Internal Server Error: /api/v1/snippets
Traceback (most recent call last):
  File "/server/software/pyenv/versions/2.7.5/lib/python2.7/site-packages/django/core/handlers/base.py", line 108, in get_response
    response = middleware_method(request)
  File "/server/software/pyenv/versions/2.7.5/lib/python2.7/site-packages/django/middleware/common.py", line 74, in process_request
    if (not urlresolvers.is_valid_path(request.path_info, urlconf) and
  File "/server/software/pyenv/versions/2.7.5/lib/python2.7/site-packages/django/core/urlresolvers.py", line 647, in is_valid_path
    resolve(path, urlconf)
  File "/server/software/pyenv/versions/2.7.5/lib/python2.7/site-packages/django/core/urlresolvers.py", line 522, in resolve
    return get_resolver(urlconf).resolve(path)
  File "/server/software/pyenv/versions/2.7.5/lib/python2.7/site-packages/django/core/urlresolvers.py", line 366, in resolve
    for pattern in self.url_patterns:
  File "/server/software/pyenv/versions/2.7.5/lib/python2.7/site-packages/django/core/urlresolvers.py", line 402, in url_patterns
    patterns = getattr(self.urlconf_module, "urlpatterns", self.urlconf_module)
  File "/server/software/pyenv/versions/2.7.5/lib/python2.7/site-packages/django/core/urlresolvers.py", line 396, in urlconf_module
    self._urlconf_module = import_module(self.urlconf_name)
  File "/server/software/pyenv/versions/2.7.5/lib/python2.7/importlib/__init__.py", line 37, in import_module
    __import__(name)
  File "/server/software/OpManage/OpManage/urls.py", line 27, in <module>
    url(r'^api/v1/',include('Api.urls')), #settings中注册app后使用单引号不需要import
  File "/server/software/pyenv/versions/2.7.5/lib/python2.7/site-packages/django/conf/urls/__init__.py", line 33, in include
    urlconf_module = import_module(urlconf_module)
  File "/server/software/pyenv/versions/2.7.5/lib/python2.7/importlib/__init__.py", line 37, in import_module
    __import__(name)
  File "/server/software/OpManage/Api/urls.py", line 12, in <module>
    from Api.views import *
  File "/server/software/OpManage/Api/views.py", line 44
    """
    查看、编辑组的界面
    """
      
                               
       ^
IndentationError: expected an indented block
2016-08-03 15:56:20,974 [Thread-4:140399039371008] [django.request:256] [base:handle_uncaught_exception] [ERROR]- Internal Server Error: /api/v1/snippets
Traceback (most recent call last):
  File "/server/software/pyenv/versions/2.7.5/lib/python2.7/site-packages/django/core/handlers/base.py", line 108, in get_response
    response = middleware_method(request)
  File "/server/software/pyenv/versions/2.7.5/lib/python2.7/site-packages/django/middleware/common.py", line 74, in process_request
    if (not urlresolvers.is_valid_path(request.path_info, urlconf) and
  File "/server/software/pyenv/versions/2.7.5/lib/python2.7/site-packages/django/core/urlresolvers.py", line 647, in is_valid_path
    resolve(path, urlconf)
  File "/server/software/pyenv/versions/2.7.5/lib/python2.7/site-packages/django/core/urlresolvers.py", line 522, in resolve
    return get_resolver(urlconf).resolve(path)
  File "/server/software/pyenv/versions/2.7.5/lib/python2.7/site-packages/django/core/urlresolvers.py", line 366, in resolve
    for pattern in self.url_patterns:
  File "/server/software/pyenv/versions/2.7.5/lib/python2.7/site-packages/django/core/urlresolvers.py", line 402, in url_patterns
    patterns = getattr(self.urlconf_module, "urlpatterns", self.urlconf_module)
  File "/server/software/pyenv/versions/2.7.5/lib/python2.7/site-packages/django/core/urlresolvers.py", line 396, in urlconf_module
    self._urlconf_module = import_module(self.urlconf_name)
  File "/server/software/pyenv/versions/2.7.5/lib/python2.7/importlib/__init__.py", line 37, in import_module
    __import__(name)
  File "/server/software/OpManage/OpManage/urls.py", line 27, in <module>
    url(r'^api/v1/',include('Api.urls')), #settings中注册app后使用单引号不需要import
  File "/server/software/pyenv/versions/2.7.5/lib/python2.7/site-packages/django/conf/urls/__init__.py", line 33, in include
    urlconf_module = import_module(urlconf_module)
  File "/server/software/pyenv/versions/2.7.5/lib/python2.7/importlib/__init__.py", line 37, in import_module
    __import__(name)
  File "/server/software/OpManage/Api/urls.py", line 12, in <module>
    from Api.views import *
  File "/server/software/OpManage/Api/views.py", line 44
    """
    查看、编辑组的界面
    """
      
                               
       ^
IndentationError: expected an indented block
2016-08-03 15:56:21,501 [Thread-5:140399039371008] [django.request:256] [base:handle_uncaught_exception] [ERROR]- Internal Server Error: /api/v1/snippets
Traceback (most recent call last):
  File "/server/software/pyenv/versions/2.7.5/lib/python2.7/site-packages/django/core/handlers/base.py", line 108, in get_response
    response = middleware_method(request)
  File "/server/software/pyenv/versions/2.7.5/lib/python2.7/site-packages/django/middleware/common.py", line 74, in process_request
    if (not urlresolvers.is_valid_path(request.path_info, urlconf) and
  File "/server/software/pyenv/versions/2.7.5/lib/python2.7/site-packages/django/core/urlresolvers.py", line 647, in is_valid_path
    resolve(path, urlconf)
  File "/server/software/pyenv/versions/2.7.5/lib/python2.7/site-packages/django/core/urlresolvers.py", line 522, in resolve
    return get_resolver(urlconf).resolve(path)
  File "/server/software/pyenv/versions/2.7.5/lib/python2.7/site-packages/django/core/urlresolvers.py", line 366, in resolve
    for pattern in self.url_patterns:
  File "/server/software/pyenv/versions/2.7.5/lib/python2.7/site-packages/django/core/urlresolvers.py", line 402, in url_patterns
    patterns = getattr(self.urlconf_module, "urlpatterns", self.urlconf_module)
  File "/server/software/pyenv/versions/2.7.5/lib/python2.7/site-packages/django/core/urlresolvers.py", line 396, in urlconf_module
    self._urlconf_module = import_module(self.urlconf_name)
  File "/server/software/pyenv/versions/2.7.5/lib/python2.7/importlib/__init__.py", line 37, in import_module
    __import__(name)
  File "/server/software/OpManage/OpManage/urls.py", line 27, in <module>
    url(r'^api/v1/',include('Api.urls')), #settings中注册app后使用单引号不需要import
  File "/server/software/pyenv/versions/2.7.5/lib/python2.7/site-packages/django/conf/urls/__init__.py", line 33, in include
    urlconf_module = import_module(urlconf_module)
  File "/server/software/pyenv/versions/2.7.5/lib/python2.7/importlib/__init__.py", line 37, in import_module
    __import__(name)
  File "/server/software/OpManage/Api/urls.py", line 12, in <module>
    from Api.views import *
  File "/server/software/OpManage/Api/views.py", line 44
    """
    查看、编辑组的界面
    """
      
                               
       ^
IndentationError: expected an indented block
2016-08-03 15:56:21,646 [Thread-6:140399023625984] [django.request:256] [base:handle_uncaught_exception] [ERROR]- Internal Server Error: /api/v1/snippets
Traceback (most recent call last):
  File "/server/software/pyenv/versions/2.7.5/lib/python2.7/site-packages/django/core/handlers/base.py", line 108, in get_response
    response = middleware_method(request)
  File "/server/software/pyenv/versions/2.7.5/lib/python2.7/site-packages/django/middleware/common.py", line 74, in process_request
    if (not urlresolvers.is_valid_path(request.path_info, urlconf) and
  File "/server/software/pyenv/versions/2.7.5/lib/python2.7/site-packages/django/core/urlresolvers.py", line 647, in is_valid_path
    resolve(path, urlconf)
  File "/server/software/pyenv/versions/2.7.5/lib/python2.7/site-packages/django/core/urlresolvers.py", line 522, in resolve
    return get_resolver(urlconf).resolve(path)
  File "/server/software/pyenv/versions/2.7.5/lib/python2.7/site-packages/django/core/urlresolvers.py", line 366, in resolve
    for pattern in self.url_patterns:
  File "/server/software/pyenv/versions/2.7.5/lib/python2.7/site-packages/django/core/urlresolvers.py", line 402, in url_patterns
    patterns = getattr(self.urlconf_module, "urlpatterns", self.urlconf_module)
  File "/server/software/pyenv/versions/2.7.5/lib/python2.7/site-packages/django/core/urlresolvers.py", line 396, in urlconf_module
    self._urlconf_module = import_module(self.urlconf_name)
  File "/server/software/pyenv/versions/2.7.5/lib/python2.7/importlib/__init__.py", line 37, in import_module
    __import__(name)
  File "/server/software/OpManage/OpManage/urls.py", line 27, in <module>
    url(r'^api/v1/',include('Api.urls')), #settings中注册app后使用单引号不需要import
  File "/server/software/pyenv/versions/2.7.5/lib/python2.7/site-packages/django/conf/urls/__init__.py", line 33, in include
    urlconf_module = import_module(urlconf_module)
  File "/server/software/pyenv/versions/2.7.5/lib/python2.7/importlib/__init__.py", line 37, in import_module
    __import__(name)
  File "/server/software/OpManage/Api/urls.py", line 12, in <module>
    from Api.views import *
  File "/server/software/OpManage/Api/views.py", line 44
    """
    查看、编辑组的界面
    """
      
                               
       ^
IndentationError: expected an indented block
2016-08-03 15:56:21,758 [Thread-7:140399023625984] [django.request:256] [base:handle_uncaught_exception] [ERROR]- Internal Server Error: /api/v1/snippets
Traceback (most recent call last):
  File "/server/software/pyenv/versions/2.7.5/lib/python2.7/site-packages/django/core/handlers/base.py", line 108, in get_response
    response = middleware_method(request)
  File "/server/software/pyenv/versions/2.7.5/lib/python2.7/site-packages/django/middleware/common.py", line 74, in process_request
    if (not urlresolvers.is_valid_path(request.path_info, urlconf) and
  File "/server/software/pyenv/versions/2.7.5/lib/python2.7/site-packages/django/core/urlresolvers.py", line 647, in is_valid_path
    resolve(path, urlconf)
  File "/server/software/pyenv/versions/2.7.5/lib/python2.7/site-packages/django/core/urlresolvers.py", line 522, in resolve
    return get_resolver(urlconf).resolve(path)
  File "/server/software/pyenv/versions/2.7.5/lib/python2.7/site-packages/django/core/urlresolvers.py", line 366, in resolve
    for pattern in self.url_patterns:
  File "/server/software/pyenv/versions/2.7.5/lib/python2.7/site-packages/django/core/urlresolvers.py", line 402, in url_patterns
    patterns = getattr(self.urlconf_module, "urlpatterns", self.urlconf_module)
  File "/server/software/pyenv/versions/2.7.5/lib/python2.7/site-packages/django/core/urlresolvers.py", line 396, in urlconf_module
    self._urlconf_module = import_module(self.urlconf_name)
  File "/server/software/pyenv/versions/2.7.5/lib/python2.7/importlib/__init__.py", line 37, in import_module
    __import__(name)
  File "/server/software/OpManage/OpManage/urls.py", line 27, in <module>
    url(r'^api/v1/',include('Api.urls')), #settings中注册app后使用单引号不需要import
  File "/server/software/pyenv/versions/2.7.5/lib/python2.7/site-packages/django/conf/urls/__init__.py", line 33, in include
    urlconf_module = import_module(urlconf_module)
  File "/server/software/pyenv/versions/2.7.5/lib/python2.7/importlib/__init__.py", line 37, in import_module
    __import__(name)
  File "/server/software/OpManage/Api/urls.py", line 12, in <module>
    from Api.views import *
  File "/server/software/OpManage/Api/views.py", line 44
    """
    查看、编辑组的界面
    """
      
                               
       ^
IndentationError: expected an indented block
2016-08-03 15:56:21,914 [Thread-8:140399039371008] [django.request:256] [base:handle_uncaught_exception] [ERROR]- Internal Server Error: /api/v1/snippets
Traceback (most recent call last):
  File "/server/software/pyenv/versions/2.7.5/lib/python2.7/site-packages/django/core/handlers/base.py", line 108, in get_response
    response = middleware_method(request)
  File "/server/software/pyenv/versions/2.7.5/lib/python2.7/site-packages/django/middleware/common.py", line 74, in process_request
    if (not urlresolvers.is_valid_path(request.path_info, urlconf) and
  File "/server/software/pyenv/versions/2.7.5/lib/python2.7/site-packages/django/core/urlresolvers.py", line 647, in is_valid_path
    resolve(path, urlconf)
  File "/server/software/pyenv/versions/2.7.5/lib/python2.7/site-packages/django/core/urlresolvers.py", line 522, in resolve
    return get_resolver(urlconf).resolve(path)
  File "/server/software/pyenv/versions/2.7.5/lib/python2.7/site-packages/django/core/urlresolvers.py", line 366, in resolve
    for pattern in self.url_patterns:
  File "/server/software/pyenv/versions/2.7.5/lib/python2.7/site-packages/django/core/urlresolvers.py", line 402, in url_patterns
    patterns = getattr(self.urlconf_module, "urlpatterns", self.urlconf_module)
  File "/server/software/pyenv/versions/2.7.5/lib/python2.7/site-packages/django/core/urlresolvers.py", line 396, in urlconf_module
    self._urlconf_module = import_module(self.urlconf_name)
  File "/server/software/pyenv/versions/2.7.5/lib/python2.7/importlib/__init__.py", line 37, in import_module
    __import__(name)
  File "/server/software/OpManage/OpManage/urls.py", line 27, in <module>
    url(r'^api/v1/',include('Api.urls')), #settings中注册app后使用单引号不需要import
  File "/server/software/pyenv/versions/2.7.5/lib/python2.7/site-packages/django/conf/urls/__init__.py", line 33, in include
    urlconf_module = import_module(urlconf_module)
  File "/server/software/pyenv/versions/2.7.5/lib/python2.7/importlib/__init__.py", line 37, in import_module
    __import__(name)
  File "/server/software/OpManage/Api/urls.py", line 12, in <module>
    from Api.views import *
  File "/server/software/OpManage/Api/views.py", line 44
    """
    查看、编辑组的界面
    """
      
                               
       ^
IndentationError: expected an indented block
2016-08-03 15:56:22,022 [Thread-9:140399023625984] [django.request:256] [base:handle_uncaught_exception] [ERROR]- Internal Server Error: /api/v1/snippets
Traceback (most recent call last):
  File "/server/software/pyenv/versions/2.7.5/lib/python2.7/site-packages/django/core/handlers/base.py", line 108, in get_response
    response = middleware_method(request)
  File "/server/software/pyenv/versions/2.7.5/lib/python2.7/site-packages/django/middleware/common.py", line 74, in process_request
    if (not urlresolvers.is_valid_path(request.path_info, urlconf) and
  File "/server/software/pyenv/versions/2.7.5/lib/python2.7/site-packages/django/core/urlresolvers.py", line 647, in is_valid_path
    resolve(path, urlconf)
  File "/server/software/pyenv/versions/2.7.5/lib/python2.7/site-packages/django/core/urlresolvers.py", line 522, in resolve
    return get_resolver(urlconf).resolve(path)
  File "/server/software/pyenv/versions/2.7.5/lib/python2.7/site-packages/django/core/urlresolvers.py", line 366, in resolve
    for pattern in self.url_patterns:
  File "/server/software/pyenv/versions/2.7.5/lib/python2.7/site-packages/django/core/urlresolvers.py", line 402, in url_patterns
    patterns = getattr(self.urlconf_module, "urlpatterns", self.urlconf_module)
  File "/server/software/pyenv/versions/2.7.5/lib/python2.7/site-packages/django/core/urlresolvers.py", line 396, in urlconf_module
    self._urlconf_module = import_module(self.urlconf_name)
  File "/server/software/pyenv/versions/2.7.5/lib/python2.7/importlib/__init__.py", line 37, in import_module
    __import__(name)
  File "/server/software/OpManage/OpManage/urls.py", line 27, in <module>
    url(r'^api/v1/',include('Api.urls')), #settings中注册app后使用单引号不需要import
  File "/server/software/pyenv/versions/2.7.5/lib/python2.7/site-packages/django/conf/urls/__init__.py", line 33, in include
    urlconf_module = import_module(urlconf_module)
  File "/server/software/pyenv/versions/2.7.5/lib/python2.7/importlib/__init__.py", line 37, in import_module
    __import__(name)
  File "/server/software/OpManage/Api/urls.py", line 12, in <module>
    from Api.views import *
  File "/server/software/OpManage/Api/views.py", line 44
    """
    查看、编辑组的界面
    """
      
                               
       ^
IndentationError: expected an indented block
2016-08-03 15:56:22,242 [Thread-10:140399039371008] [django.request:256] [base:handle_uncaught_exception] [ERROR]- Internal Server Error: /api/v1/snippets
Traceback (most recent call last):
  File "/server/software/pyenv/versions/2.7.5/lib/python2.7/site-packages/django/core/handlers/base.py", line 108, in get_response
    response = middleware_method(request)
  File "/server/software/pyenv/versions/2.7.5/lib/python2.7/site-packages/django/middleware/common.py", line 74, in process_request
    if (not urlresolvers.is_valid_path(request.path_info, urlconf) and
  File "/server/software/pyenv/versions/2.7.5/lib/python2.7/site-packages/django/core/urlresolvers.py", line 647, in is_valid_path
    resolve(path, urlconf)
  File "/server/software/pyenv/versions/2.7.5/lib/python2.7/site-packages/django/core/urlresolvers.py", line 522, in resolve
    return get_resolver(urlconf).resolve(path)
  File "/server/software/pyenv/versions/2.7.5/lib/python2.7/site-packages/django/core/urlresolvers.py", line 366, in resolve
    for pattern in self.url_patterns:
  File "/server/software/pyenv/versions/2.7.5/lib/python2.7/site-packages/django/core/urlresolvers.py", line 402, in url_patterns
    patterns = getattr(self.urlconf_module, "urlpatterns", self.urlconf_module)
  File "/server/software/pyenv/versions/2.7.5/lib/python2.7/site-packages/django/core/urlresolvers.py", line 396, in urlconf_module
    self._urlconf_module = import_module(self.urlconf_name)
  File "/server/software/pyenv/versions/2.7.5/lib/python2.7/importlib/__init__.py", line 37, in import_module
    __import__(name)
  File "/server/software/OpManage/OpManage/urls.py", line 27, in <module>
    url(r'^api/v1/',include('Api.urls')), #settings中注册app后使用单引号不需要import
  File "/server/software/pyenv/versions/2.7.5/lib/python2.7/site-packages/django/conf/urls/__init__.py", line 33, in include
    urlconf_module = import_module(urlconf_module)
  File "/server/software/pyenv/versions/2.7.5/lib/python2.7/importlib/__init__.py", line 37, in import_module
    __import__(name)
  File "/server/software/OpManage/Api/urls.py", line 12, in <module>
    from Api.views import *
  File "/server/software/OpManage/Api/views.py", line 44
    """
    查看、编辑组的界面
    """
      
                               
       ^
IndentationError: expected an indented block
2016-08-03 15:56:22,282 [Thread-11:140399023625984] [django.request:256] [base:handle_uncaught_exception] [ERROR]- Internal Server Error: /api/v1/snippets
Traceback (most recent call last):
  File "/server/software/pyenv/versions/2.7.5/lib/python2.7/site-packages/django/core/handlers/base.py", line 108, in get_response
    response = middleware_method(request)
  File "/server/software/pyenv/versions/2.7.5/lib/python2.7/site-packages/django/middleware/common.py", line 74, in process_request
    if (not urlresolvers.is_valid_path(request.path_info, urlconf) and
  File "/server/software/pyenv/versions/2.7.5/lib/python2.7/site-packages/django/core/urlresolvers.py", line 647, in is_valid_path
    resolve(path, urlconf)
  File "/server/software/pyenv/versions/2.7.5/lib/python2.7/site-packages/django/core/urlresolvers.py", line 522, in resolve
    return get_resolver(urlconf).resolve(path)
  File "/server/software/pyenv/versions/2.7.5/lib/python2.7/site-packages/django/core/urlresolvers.py", line 366, in resolve
    for pattern in self.url_patterns:
  File "/server/software/pyenv/versions/2.7.5/lib/python2.7/site-packages/django/core/urlresolvers.py", line 402, in url_patterns
    patterns = getattr(self.urlconf_module, "urlpatterns", self.urlconf_module)
  File "/server/software/pyenv/versions/2.7.5/lib/python2.7/site-packages/django/core/urlresolvers.py", line 396, in urlconf_module
    self._urlconf_module = import_module(self.urlconf_name)
  File "/server/software/pyenv/versions/2.7.5/lib/python2.7/importlib/__init__.py", line 37, in import_module
    __import__(name)
  File "/server/software/OpManage/OpManage/urls.py", line 27, in <module>
    url(r'^api/v1/',include('Api.urls')), #settings中注册app后使用单引号不需要import
  File "/server/software/pyenv/versions/2.7.5/lib/python2.7/site-packages/django/conf/urls/__init__.py", line 33, in include
    urlconf_module = import_module(urlconf_module)
  File "/server/software/pyenv/versions/2.7.5/lib/python2.7/importlib/__init__.py", line 37, in import_module
    __import__(name)
  File "/server/software/OpManage/Api/urls.py", line 12, in <module>
    from Api.views import *
  File "/server/software/OpManage/Api/views.py", line 44
    """
    查看、编辑组的界面
    """
      
                               
       ^
IndentationError: expected an indented block
2016-08-03 15:56:22,497 [Thread-12:140399013136128] [django.request:256] [base:handle_uncaught_exception] [ERROR]- Internal Server Error: /api/v1/snippets
Traceback (most recent call last):
  File "/server/software/pyenv/versions/2.7.5/lib/python2.7/site-packages/django/core/handlers/base.py", line 108, in get_response
    response = middleware_method(request)
  File "/server/software/pyenv/versions/2.7.5/lib/python2.7/site-packages/django/middleware/common.py", line 74, in process_request
    if (not urlresolvers.is_valid_path(request.path_info, urlconf) and
  File "/server/software/pyenv/versions/2.7.5/lib/python2.7/site-packages/django/core/urlresolvers.py", line 647, in is_valid_path
    resolve(path, urlconf)
  File "/server/software/pyenv/versions/2.7.5/lib/python2.7/site-packages/django/core/urlresolvers.py", line 522, in resolve
    return get_resolver(urlconf).resolve(path)
  File "/server/software/pyenv/versions/2.7.5/lib/python2.7/site-packages/django/core/urlresolvers.py", line 366, in resolve
    for pattern in self.url_patterns:
  File "/server/software/pyenv/versions/2.7.5/lib/python2.7/site-packages/django/core/urlresolvers.py", line 402, in url_patterns
    patterns = getattr(self.urlconf_module, "urlpatterns", self.urlconf_module)
  File "/server/software/pyenv/versions/2.7.5/lib/python2.7/site-packages/django/core/urlresolvers.py", line 396, in urlconf_module
    self._urlconf_module = import_module(self.urlconf_name)
  File "/server/software/pyenv/versions/2.7.5/lib/python2.7/importlib/__init__.py", line 37, in import_module
    __import__(name)
  File "/server/software/OpManage/OpManage/urls.py", line 27, in <module>
    url(r'^api/v1/',include('Api.urls')), #settings中注册app后使用单引号不需要import
  File "/server/software/pyenv/versions/2.7.5/lib/python2.7/site-packages/django/conf/urls/__init__.py", line 33, in include
    urlconf_module = import_module(urlconf_module)
  File "/server/software/pyenv/versions/2.7.5/lib/python2.7/importlib/__init__.py", line 37, in import_module
    __import__(name)
  File "/server/software/OpManage/Api/urls.py", line 12, in <module>
    from Api.views import *
  File "/server/software/OpManage/Api/views.py", line 44
    """
    查看、编辑组的界面
    """
      
                               
       ^
IndentationError: expected an indented block
2016-08-03 15:56:22,543 [Thread-13:140399002646272] [django.request:256] [base:handle_uncaught_exception] [ERROR]- Internal Server Error: /api/v1/snippets
Traceback (most recent call last):
  File "/server/software/pyenv/versions/2.7.5/lib/python2.7/site-packages/django/core/handlers/base.py", line 108, in get_response
    response = middleware_method(request)
  File "/server/software/pyenv/versions/2.7.5/lib/python2.7/site-packages/django/middleware/common.py", line 74, in process_request
    if (not urlresolvers.is_valid_path(request.path_info, urlconf) and
  File "/server/software/pyenv/versions/2.7.5/lib/python2.7/site-packages/django/core/urlresolvers.py", line 647, in is_valid_path
    resolve(path, urlconf)
  File "/server/software/pyenv/versions/2.7.5/lib/python2.7/site-packages/django/core/urlresolvers.py", line 522, in resolve
    return get_resolver(urlconf).resolve(path)
  File "/server/software/pyenv/versions/2.7.5/lib/python2.7/site-packages/django/core/urlresolvers.py", line 366, in resolve
    for pattern in self.url_patterns:
  File "/server/software/pyenv/versions/2.7.5/lib/python2.7/site-packages/django/core/urlresolvers.py", line 402, in url_patterns
    patterns = getattr(self.urlconf_module, "urlpatterns", self.urlconf_module)
  File "/server/software/pyenv/versions/2.7.5/lib/python2.7/site-packages/django/core/urlresolvers.py", line 396, in urlconf_module
    self._urlconf_module = import_module(self.urlconf_name)
  File "/server/software/pyenv/versions/2.7.5/lib/python2.7/importlib/__init__.py", line 37, in import_module
    __import__(name)
  File "/server/software/OpManage/OpManage/urls.py", line 27, in <module>
    url(r'^api/v1/',include('Api.urls')), #settings中注册app后使用单引号不需要import
  File "/server/software/pyenv/versions/2.7.5/lib/python2.7/site-packages/django/conf/urls/__init__.py", line 33, in include
    urlconf_module = import_module(urlconf_module)
  File "/server/software/pyenv/versions/2.7.5/lib/python2.7/importlib/__init__.py", line 37, in import_module
    __import__(name)
  File "/server/software/OpManage/Api/urls.py", line 12, in <module>
    from Api.views import *
  File "/server/software/OpManage/Api/views.py", line 44
    """
    查看、编辑组的界面
    """
      
                               
       ^
IndentationError: expected an indented block
2016-08-03 15:56:22,680 [Thread-14:140399039371008] [django.request:256] [base:handle_uncaught_exception] [ERROR]- Internal Server Error: /api/v1/snippets
Traceback (most recent call last):
  File "/server/software/pyenv/versions/2.7.5/lib/python2.7/site-packages/django/core/handlers/base.py", line 108, in get_response
    response = middleware_method(request)
  File "/server/software/pyenv/versions/2.7.5/lib/python2.7/site-packages/django/middleware/common.py", line 74, in process_request
    if (not urlresolvers.is_valid_path(request.path_info, urlconf) and
  File "/server/software/pyenv/versions/2.7.5/lib/python2.7/site-packages/django/core/urlresolvers.py", line 647, in is_valid_path
    resolve(path, urlconf)
  File "/server/software/pyenv/versions/2.7.5/lib/python2.7/site-packages/django/core/urlresolvers.py", line 522, in resolve
    return get_resolver(urlconf).resolve(path)
  File "/server/software/pyenv/versions/2.7.5/lib/python2.7/site-packages/django/core/urlresolvers.py", line 366, in resolve
    for pattern in self.url_patterns:
  File "/server/software/pyenv/versions/2.7.5/lib/python2.7/site-packages/django/core/urlresolvers.py", line 402, in url_patterns
    patterns = getattr(self.urlconf_module, "urlpatterns", self.urlconf_module)
  File "/server/software/pyenv/versions/2.7.5/lib/python2.7/site-packages/django/core/urlresolvers.py", line 396, in urlconf_module
    self._urlconf_module = import_module(self.urlconf_name)
  File "/server/software/pyenv/versions/2.7.5/lib/python2.7/importlib/__init__.py", line 37, in import_module
    __import__(name)
  File "/server/software/OpManage/OpManage/urls.py", line 27, in <module>
    url(r'^api/v1/',include('Api.urls')), #settings中注册app后使用单引号不需要import
  File "/server/software/pyenv/versions/2.7.5/lib/python2.7/site-packages/django/conf/urls/__init__.py", line 33, in include
    urlconf_module = import_module(urlconf_module)
  File "/server/software/pyenv/versions/2.7.5/lib/python2.7/importlib/__init__.py", line 37, in import_module
    __import__(name)
  File "/server/software/OpManage/Api/urls.py", line 12, in <module>
    from Api.views import *
  File "/server/software/OpManage/Api/views.py", line 44
    """
    查看、编辑组的界面
    """
      
                               
       ^
IndentationError: expected an indented block
2016-08-03 15:56:22,811 [Thread-15:140399023625984] [django.request:256] [base:handle_uncaught_exception] [ERROR]- Internal Server Error: /api/v1/snippets
Traceback (most recent call last):
  File "/server/software/pyenv/versions/2.7.5/lib/python2.7/site-packages/django/core/handlers/base.py", line 108, in get_response
    response = middleware_method(request)
  File "/server/software/pyenv/versions/2.7.5/lib/python2.7/site-packages/django/middleware/common.py", line 74, in process_request
    if (not urlresolvers.is_valid_path(request.path_info, urlconf) and
  File "/server/software/pyenv/versions/2.7.5/lib/python2.7/site-packages/django/core/urlresolvers.py", line 647, in is_valid_path
    resolve(path, urlconf)
  File "/server/software/pyenv/versions/2.7.5/lib/python2.7/site-packages/django/core/urlresolvers.py", line 522, in resolve
    return get_resolver(urlconf).resolve(path)
  File "/server/software/pyenv/versions/2.7.5/lib/python2.7/site-packages/django/core/urlresolvers.py", line 366, in resolve
    for pattern in self.url_patterns:
  File "/server/software/pyenv/versions/2.7.5/lib/python2.7/site-packages/django/core/urlresolvers.py", line 402, in url_patterns
    patterns = getattr(self.urlconf_module, "urlpatterns", self.urlconf_module)
  File "/server/software/pyenv/versions/2.7.5/lib/python2.7/site-packages/django/core/urlresolvers.py", line 396, in urlconf_module
    self._urlconf_module = import_module(self.urlconf_name)
  File "/server/software/pyenv/versions/2.7.5/lib/python2.7/importlib/__init__.py", line 37, in import_module
    __import__(name)
  File "/server/software/OpManage/OpManage/urls.py", line 27, in <module>
    url(r'^api/v1/',include('Api.urls')), #settings中注册app后使用单引号不需要import
  File "/server/software/pyenv/versions/2.7.5/lib/python2.7/site-packages/django/conf/urls/__init__.py", line 33, in include
    urlconf_module = import_module(urlconf_module)
  File "/server/software/pyenv/versions/2.7.5/lib/python2.7/importlib/__init__.py", line 37, in import_module
    __import__(name)
  File "/server/software/OpManage/Api/urls.py", line 12, in <module>
    from Api.views import *
  File "/server/software/OpManage/Api/views.py", line 44
    """
    查看、编辑组的界面
    """
      
                               
       ^
IndentationError: expected an indented block
2016-08-03 15:56:22,987 [Thread-16:140398655698688] [django.request:256] [base:handle_uncaught_exception] [ERROR]- Internal Server Error: /api/v1/snippets
Traceback (most recent call last):
  File "/server/software/pyenv/versions/2.7.5/lib/python2.7/site-packages/django/core/handlers/base.py", line 108, in get_response
    response = middleware_method(request)
  File "/server/software/pyenv/versions/2.7.5/lib/python2.7/site-packages/django/middleware/common.py", line 74, in process_request
    if (not urlresolvers.is_valid_path(request.path_info, urlconf) and
  File "/server/software/pyenv/versions/2.7.5/lib/python2.7/site-packages/django/core/urlresolvers.py", line 647, in is_valid_path
    resolve(path, urlconf)
  File "/server/software/pyenv/versions/2.7.5/lib/python2.7/site-packages/django/core/urlresolvers.py", line 522, in resolve
    return get_resolver(urlconf).resolve(path)
  File "/server/software/pyenv/versions/2.7.5/lib/python2.7/site-packages/django/core/urlresolvers.py", line 366, in resolve
    for pattern in self.url_patterns:
  File "/server/software/pyenv/versions/2.7.5/lib/python2.7/site-packages/django/core/urlresolvers.py", line 402, in url_patterns
    patterns = getattr(self.urlconf_module, "urlpatterns", self.urlconf_module)
  File "/server/software/pyenv/versions/2.7.5/lib/python2.7/site-packages/django/core/urlresolvers.py", line 396, in urlconf_module
    self._urlconf_module = import_module(self.urlconf_name)
  File "/server/software/pyenv/versions/2.7.5/lib/python2.7/importlib/__init__.py", line 37, in import_module
    __import__(name)
  File "/server/software/OpManage/OpManage/urls.py", line 27, in <module>
    url(r'^api/v1/',include('Api.urls')), #settings中注册app后使用单引号不需要import
  File "/server/software/pyenv/versions/2.7.5/lib/python2.7/site-packages/django/conf/urls/__init__.py", line 33, in include
    urlconf_module = import_module(urlconf_module)
  File "/server/software/pyenv/versions/2.7.5/lib/python2.7/importlib/__init__.py", line 37, in import_module
    __import__(name)
  File "/server/software/OpManage/Api/urls.py", line 12, in <module>
    from Api.views import *
  File "/server/software/OpManage/Api/views.py", line 44
    """
    查看、编辑组的界面
    """
      
                               
       ^
IndentationError: expected an indented block
2016-08-03 15:56:23,082 [Thread-17:140398645208832] [django.request:256] [base:handle_uncaught_exception] [ERROR]- Internal Server Error: /api/v1/snippets
Traceback (most recent call last):
  File "/server/software/pyenv/versions/2.7.5/lib/python2.7/site-packages/django/core/handlers/base.py", line 108, in get_response
    response = middleware_method(request)
  File "/server/software/pyenv/versions/2.7.5/lib/python2.7/site-packages/django/middleware/common.py", line 74, in process_request
    if (not urlresolvers.is_valid_path(request.path_info, urlconf) and
  File "/server/software/pyenv/versions/2.7.5/lib/python2.7/site-packages/django/core/urlresolvers.py", line 647, in is_valid_path
    resolve(path, urlconf)
  File "/server/software/pyenv/versions/2.7.5/lib/python2.7/site-packages/django/core/urlresolvers.py", line 522, in resolve
    return get_resolver(urlconf).resolve(path)
  File "/server/software/pyenv/versions/2.7.5/lib/python2.7/site-packages/django/core/urlresolvers.py", line 366, in resolve
    for pattern in self.url_patterns:
  File "/server/software/pyenv/versions/2.7.5/lib/python2.7/site-packages/django/core/urlresolvers.py", line 402, in url_patterns
    patterns = getattr(self.urlconf_module, "urlpatterns", self.urlconf_module)
  File "/server/software/pyenv/versions/2.7.5/lib/python2.7/site-packages/django/core/urlresolvers.py", line 396, in urlconf_module
    self._urlconf_module = import_module(self.urlconf_name)
  File "/server/software/pyenv/versions/2.7.5/lib/python2.7/importlib/__init__.py", line 37, in import_module
    __import__(name)
  File "/server/software/OpManage/OpManage/urls.py", line 27, in <module>
    url(r'^api/v1/',include('Api.urls')), #settings中注册app后使用单引号不需要import
  File "/server/software/pyenv/versions/2.7.5/lib/python2.7/site-packages/django/conf/urls/__init__.py", line 33, in include
    urlconf_module = import_module(urlconf_module)
  File "/server/software/pyenv/versions/2.7.5/lib/python2.7/importlib/__init__.py", line 37, in import_module
    __import__(name)
  File "/server/software/OpManage/Api/urls.py", line 12, in <module>
    from Api.views import *
  File "/server/software/OpManage/Api/views.py", line 44
    """
    查看、编辑组的界面
    """
      
                               
       ^
IndentationError: expected an indented block
2016-08-03 15:56:23,190 [Thread-18:140399002646272] [django.request:256] [base:handle_uncaught_exception] [ERROR]- Internal Server Error: /api/v1/snippets
Traceback (most recent call last):
  File "/server/software/pyenv/versions/2.7.5/lib/python2.7/site-packages/django/core/handlers/base.py", line 108, in get_response
    response = middleware_method(request)
  File "/server/software/pyenv/versions/2.7.5/lib/python2.7/site-packages/django/middleware/common.py", line 74, in process_request
    if (not urlresolvers.is_valid_path(request.path_info, urlconf) and
  File "/server/software/pyenv/versions/2.7.5/lib/python2.7/site-packages/django/core/urlresolvers.py", line 647, in is_valid_path
    resolve(path, urlconf)
  File "/server/software/pyenv/versions/2.7.5/lib/python2.7/site-packages/django/core/urlresolvers.py", line 522, in resolve
    return get_resolver(urlconf).resolve(path)
  File "/server/software/pyenv/versions/2.7.5/lib/python2.7/site-packages/django/core/urlresolvers.py", line 366, in resolve
    for pattern in self.url_patterns:
  File "/server/software/pyenv/versions/2.7.5/lib/python2.7/site-packages/django/core/urlresolvers.py", line 402, in url_patterns
    patterns = getattr(self.urlconf_module, "urlpatterns", self.urlconf_module)
  File "/server/software/pyenv/versions/2.7.5/lib/python2.7/site-packages/django/core/urlresolvers.py", line 396, in urlconf_module
    self._urlconf_module = import_module(self.urlconf_name)
  File "/server/software/pyenv/versions/2.7.5/lib/python2.7/importlib/__init__.py", line 37, in import_module
    __import__(name)
  File "/server/software/OpManage/OpManage/urls.py", line 27, in <module>
    url(r'^api/v1/',include('Api.urls')), #settings中注册app后使用单引号不需要import
  File "/server/software/pyenv/versions/2.7.5/lib/python2.7/site-packages/django/conf/urls/__init__.py", line 33, in include
    urlconf_module = import_module(urlconf_module)
  File "/server/software/pyenv/versions/2.7.5/lib/python2.7/importlib/__init__.py", line 37, in import_module
    __import__(name)
  File "/server/software/OpManage/Api/urls.py", line 12, in <module>
    from Api.views import *
  File "/server/software/OpManage/Api/views.py", line 44
    """
    查看、编辑组的界面
    """
      
                               
       ^
IndentationError: expected an indented block
2016-08-03 15:56:23,309 [Thread-19:140399013136128] [django.request:256] [base:handle_uncaught_exception] [ERROR]- Internal Server Error: /api/v1/snippets
Traceback (most recent call last):
  File "/server/software/pyenv/versions/2.7.5/lib/python2.7/site-packages/django/core/handlers/base.py", line 108, in get_response
    response = middleware_method(request)
  File "/server/software/pyenv/versions/2.7.5/lib/python2.7/site-packages/django/middleware/common.py", line 74, in process_request
    if (not urlresolvers.is_valid_path(request.path_info, urlconf) and
  File "/server/software/pyenv/versions/2.7.5/lib/python2.7/site-packages/django/core/urlresolvers.py", line 647, in is_valid_path
    resolve(path, urlconf)
  File "/server/software/pyenv/versions/2.7.5/lib/python2.7/site-packages/django/core/urlresolvers.py", line 522, in resolve
    return get_resolver(urlconf).resolve(path)
  File "/server/software/pyenv/versions/2.7.5/lib/python2.7/site-packages/django/core/urlresolvers.py", line 366, in resolve
    for pattern in self.url_patterns:
  File "/server/software/pyenv/versions/2.7.5/lib/python2.7/site-packages/django/core/urlresolvers.py", line 402, in url_patterns
    patterns = getattr(self.urlconf_module, "urlpatterns", self.urlconf_module)
  File "/server/software/pyenv/versions/2.7.5/lib/python2.7/site-packages/django/core/urlresolvers.py", line 396, in urlconf_module
    self._urlconf_module = import_module(self.urlconf_name)
  File "/server/software/pyenv/versions/2.7.5/lib/python2.7/importlib/__init__.py", line 37, in import_module
    __import__(name)
  File "/server/software/OpManage/OpManage/urls.py", line 27, in <module>
    url(r'^api/v1/',include('Api.urls')), #settings中注册app后使用单引号不需要import
  File "/server/software/pyenv/versions/2.7.5/lib/python2.7/site-packages/django/conf/urls/__init__.py", line 33, in include
    urlconf_module = import_module(urlconf_module)
  File "/server/software/pyenv/versions/2.7.5/lib/python2.7/importlib/__init__.py", line 37, in import_module
    __import__(name)
  File "/server/software/OpManage/Api/urls.py", line 12, in <module>
    from Api.views import *
  File "/server/software/OpManage/Api/views.py", line 44
    """
    查看、编辑组的界面
    """
      
                               
       ^
IndentationError: expected an indented block
2016-08-03 15:56:23,450 [Thread-20:140398634718976] [django.request:256] [base:handle_uncaught_exception] [ERROR]- Internal Server Error: /api/v1/snippets
Traceback (most recent call last):
  File "/server/software/pyenv/versions/2.7.5/lib/python2.7/site-packages/django/core/handlers/base.py", line 108, in get_response
    response = middleware_method(request)
  File "/server/software/pyenv/versions/2.7.5/lib/python2.7/site-packages/django/middleware/common.py", line 74, in process_request
    if (not urlresolvers.is_valid_path(request.path_info, urlconf) and
  File "/server/software/pyenv/versions/2.7.5/lib/python2.7/site-packages/django/core/urlresolvers.py", line 647, in is_valid_path
    resolve(path, urlconf)
  File "/server/software/pyenv/versions/2.7.5/lib/python2.7/site-packages/django/core/urlresolvers.py", line 522, in resolve
    return get_resolver(urlconf).resolve(path)
  File "/server/software/pyenv/versions/2.7.5/lib/python2.7/site-packages/django/core/urlresolvers.py", line 366, in resolve
    for pattern in self.url_patterns:
  File "/server/software/pyenv/versions/2.7.5/lib/python2.7/site-packages/django/core/urlresolvers.py", line 402, in url_patterns
    patterns = getattr(self.urlconf_module, "urlpatterns", self.urlconf_module)
  File "/server/software/pyenv/versions/2.7.5/lib/python2.7/site-packages/django/core/urlresolvers.py", line 396, in urlconf_module
    self._urlconf_module = import_module(self.urlconf_name)
  File "/server/software/pyenv/versions/2.7.5/lib/python2.7/importlib/__init__.py", line 37, in import_module
    __import__(name)
  File "/server/software/OpManage/OpManage/urls.py", line 27, in <module>
    url(r'^api/v1/',include('Api.urls')), #settings中注册app后使用单引号不需要import
  File "/server/software/pyenv/versions/2.7.5/lib/python2.7/site-packages/django/conf/urls/__init__.py", line 33, in include
    urlconf_module = import_module(urlconf_module)
  File "/server/software/pyenv/versions/2.7.5/lib/python2.7/importlib/__init__.py", line 37, in import_module
    __import__(name)
  File "/server/software/OpManage/Api/urls.py", line 12, in <module>
    from Api.views import *
  File "/server/software/OpManage/Api/views.py", line 44
    """
    查看、编辑组的界面
    """
      
                               
       ^
IndentationError: expected an indented block
2016-08-03 15:56:23,565 [Thread-21:140399039371008] [django.request:256] [base:handle_uncaught_exception] [ERROR]- Internal Server Error: /api/v1/snippets
Traceback (most recent call last):
  File "/server/software/pyenv/versions/2.7.5/lib/python2.7/site-packages/django/core/handlers/base.py", line 108, in get_response
    response = middleware_method(request)
  File "/server/software/pyenv/versions/2.7.5/lib/python2.7/site-packages/django/middleware/common.py", line 74, in process_request
    if (not urlresolvers.is_valid_path(request.path_info, urlconf) and
  File "/server/software/pyenv/versions/2.7.5/lib/python2.7/site-packages/django/core/urlresolvers.py", line 647, in is_valid_path
    resolve(path, urlconf)
  File "/server/software/pyenv/versions/2.7.5/lib/python2.7/site-packages/django/core/urlresolvers.py", line 522, in resolve
    return get_resolver(urlconf).resolve(path)
  File "/server/software/pyenv/versions/2.7.5/lib/python2.7/site-packages/django/core/urlresolvers.py", line 366, in resolve
    for pattern in self.url_patterns:
  File "/server/software/pyenv/versions/2.7.5/lib/python2.7/site-packages/django/core/urlresolvers.py", line 402, in url_patterns
    patterns = getattr(self.urlconf_module, "urlpatterns", self.urlconf_module)
  File "/server/software/pyenv/versions/2.7.5/lib/python2.7/site-packages/django/core/urlresolvers.py", line 396, in urlconf_module
    self._urlconf_module = import_module(self.urlconf_name)
  File "/server/software/pyenv/versions/2.7.5/lib/python2.7/importlib/__init__.py", line 37, in import_module
    __import__(name)
  File "/server/software/OpManage/OpManage/urls.py", line 27, in <module>
    url(r'^api/v1/',include('Api.urls')), #settings中注册app后使用单引号不需要import
  File "/server/software/pyenv/versions/2.7.5/lib/python2.7/site-packages/django/conf/urls/__init__.py", line 33, in include
    urlconf_module = import_module(urlconf_module)
  File "/server/software/pyenv/versions/2.7.5/lib/python2.7/importlib/__init__.py", line 37, in import_module
    __import__(name)
  File "/server/software/OpManage/Api/urls.py", line 12, in <module>
    from Api.views import *
  File "/server/software/OpManage/Api/views.py", line 44
    """
    查看、编辑组的界面
    """
      
                               
       ^
IndentationError: expected an indented block
2016-08-03 15:56:23,682 [Thread-22:140399023625984] [django.request:256] [base:handle_uncaught_exception] [ERROR]- Internal Server Error: /api/v1/snippets
Traceback (most recent call last):
  File "/server/software/pyenv/versions/2.7.5/lib/python2.7/site-packages/django/core/handlers/base.py", line 108, in get_response
    response = middleware_method(request)
  File "/server/software/pyenv/versions/2.7.5/lib/python2.7/site-packages/django/middleware/common.py", line 74, in process_request
    if (not urlresolvers.is_valid_path(request.path_info, urlconf) and
  File "/server/software/pyenv/versions/2.7.5/lib/python2.7/site-packages/django/core/urlresolvers.py", line 647, in is_valid_path
    resolve(path, urlconf)
  File "/server/software/pyenv/versions/2.7.5/lib/python2.7/site-packages/django/core/urlresolvers.py", line 522, in resolve
    return get_resolver(urlconf).resolve(path)
  File "/server/software/pyenv/versions/2.7.5/lib/python2.7/site-packages/django/core/urlresolvers.py", line 366, in resolve
    for pattern in self.url_patterns:
  File "/server/software/pyenv/versions/2.7.5/lib/python2.7/site-packages/django/core/urlresolvers.py", line 402, in url_patterns
    patterns = getattr(self.urlconf_module, "urlpatterns", self.urlconf_module)
  File "/server/software/pyenv/versions/2.7.5/lib/python2.7/site-packages/django/core/urlresolvers.py", line 396, in urlconf_module
    self._urlconf_module = import_module(self.urlconf_name)
  File "/server/software/pyenv/versions/2.7.5/lib/python2.7/importlib/__init__.py", line 37, in import_module
    __import__(name)
  File "/server/software/OpManage/OpManage/urls.py", line 27, in <module>
    url(r'^api/v1/',include('Api.urls')), #settings中注册app后使用单引号不需要import
  File "/server/software/pyenv/versions/2.7.5/lib/python2.7/site-packages/django/conf/urls/__init__.py", line 33, in include
    urlconf_module = import_module(urlconf_module)
  File "/server/software/pyenv/versions/2.7.5/lib/python2.7/importlib/__init__.py", line 37, in import_module
    __import__(name)
  File "/server/software/OpManage/Api/urls.py", line 12, in <module>
    from Api.views import *
  File "/server/software/OpManage/Api/views.py", line 44
    """
    查看、编辑组的界面
    """
      
                               
       ^
IndentationError: expected an indented block
2016-08-03 15:56:23,793 [Thread-23:140398624229120] [django.request:256] [base:handle_uncaught_exception] [ERROR]- Internal Server Error: /api/v1/snippets
Traceback (most recent call last):
  File "/server/software/pyenv/versions/2.7.5/lib/python2.7/site-packages/django/core/handlers/base.py", line 108, in get_response
    response = middleware_method(request)
  File "/server/software/pyenv/versions/2.7.5/lib/python2.7/site-packages/django/middleware/common.py", line 74, in process_request
    if (not urlresolvers.is_valid_path(request.path_info, urlconf) and
  File "/server/software/pyenv/versions/2.7.5/lib/python2.7/site-packages/django/core/urlresolvers.py", line 647, in is_valid_path
    resolve(path, urlconf)
  File "/server/software/pyenv/versions/2.7.5/lib/python2.7/site-packages/django/core/urlresolvers.py", line 522, in resolve
    return get_resolver(urlconf).resolve(path)
  File "/server/software/pyenv/versions/2.7.5/lib/python2.7/site-packages/django/core/urlresolvers.py", line 366, in resolve
    for pattern in self.url_patterns:
  File "/server/software/pyenv/versions/2.7.5/lib/python2.7/site-packages/django/core/urlresolvers.py", line 402, in url_patterns
    patterns = getattr(self.urlconf_module, "urlpatterns", self.urlconf_module)
  File "/server/software/pyenv/versions/2.7.5/lib/python2.7/site-packages/django/core/urlresolvers.py", line 396, in urlconf_module
    self._urlconf_module = import_module(self.urlconf_name)
  File "/server/software/pyenv/versions/2.7.5/lib/python2.7/importlib/__init__.py", line 37, in import_module
    __import__(name)
  File "/server/software/OpManage/OpManage/urls.py", line 27, in <module>
    url(r'^api/v1/',include('Api.urls')), #settings中注册app后使用单引号不需要import
  File "/server/software/pyenv/versions/2.7.5/lib/python2.7/site-packages/django/conf/urls/__init__.py", line 33, in include
    urlconf_module = import_module(urlconf_module)
  File "/server/software/pyenv/versions/2.7.5/lib/python2.7/importlib/__init__.py", line 37, in import_module
    __import__(name)
  File "/server/software/OpManage/Api/urls.py", line 12, in <module>
    from Api.views import *
  File "/server/software/OpManage/Api/views.py", line 44
    """
    查看、编辑组的界面
    """
      
                               
       ^
IndentationError: expected an indented block
2016-08-03 16:00:09,161 [Thread-2:139849772300032] [django.request:256] [base:handle_uncaught_exception] [ERROR]- Internal Server Error: /api/v1/snippets/
Traceback (most recent call last):
  File "/server/software/pyenv/versions/2.7.5/lib/python2.7/site-packages/django/core/handlers/base.py", line 119, in get_response
    resolver_match = resolver.resolve(request.path_info)
  File "/server/software/pyenv/versions/2.7.5/lib/python2.7/site-packages/django/core/urlresolvers.py", line 366, in resolve
    for pattern in self.url_patterns:
  File "/server/software/pyenv/versions/2.7.5/lib/python2.7/site-packages/django/core/urlresolvers.py", line 402, in url_patterns
    patterns = getattr(self.urlconf_module, "urlpatterns", self.urlconf_module)
  File "/server/software/pyenv/versions/2.7.5/lib/python2.7/site-packages/django/core/urlresolvers.py", line 396, in urlconf_module
    self._urlconf_module = import_module(self.urlconf_name)
  File "/server/software/pyenv/versions/2.7.5/lib/python2.7/importlib/__init__.py", line 37, in import_module
    __import__(name)
  File "/server/software/OpManage/OpManage/urls.py", line 27, in <module>
    url(r'^api/v1/',include('Api.urls')), #settings中注册app后使用单引号不需要import
  File "/server/software/pyenv/versions/2.7.5/lib/python2.7/site-packages/django/conf/urls/__init__.py", line 33, in include
    urlconf_module = import_module(urlconf_module)
  File "/server/software/pyenv/versions/2.7.5/lib/python2.7/importlib/__init__.py", line 37, in import_module
    __import__(name)
  File "/server/software/OpManage/Api/urls.py", line 12, in <module>
    from Api.views import *
  File "/server/software/OpManage/Api/views.py", line 48, in <module>
    class SnippetViewSet(viewsets.ModelViewSet):
  File "/server/software/OpManage/Api/views.py", line 60, in SnippetViewSet
    assert False
AssertionError
2016-08-03 16:01:33,236 [Thread-14:139849638082304] [django.request:170] [base:get_response] [WARNING]- Not Found: /api
2016-08-03 17:39:28,311 [Thread-15:139849638082304] [django.request:170] [base:get_response] [WARNING]- Not Found: /
2016-08-10 17:02:38,831 [Thread-2:140112957486848] [django.request:170] [base:get_response] [WARNING]- Not Found: /
2016-08-10 17:02:39,091 [Thread-3:140112957486848] [django.request:170] [base:get_response] [WARNING]- Not Found: /favicon.ico
2016-09-09 13:15:52,546 [Thread-2:140261138896640] [django.request:170] [base:get_response] [WARNING]- Not Found: /
2016-09-09 13:15:52,681 [Thread-3:140261138896640] [django.request:170] [base:get_response] [WARNING]- Not Found: /favicon.ico
